Workbook

Sheet INDICE_HOJAS
B2: HOJAS
B3: RESUMEN_HNCxTIPO_porcent
B4: HNCxTIPO
B5: CALEND_REUNIONxPROF
B6: CALENDARIO_REUNIONES
B7: BORRAR_REPETIDOS
B8: BORRAR_NO _VIGENTE
B9: Horas_FUNC
B10: FUNC
B11: CONSO_ENCUESTAS
B12: ENCUESTA_GESTION
B13: ENCUESTA_REU
... B21: REF

Sheet RESUMEN_HNCxTIPO
A1: =IFERROR(__xludf.DUMMYFUNCTION("QUERY(HNCxTIPO!A3:I1000,""SELECT A,B,SUM(C) WHERE B IS NOT NULL GROUP BY A,B LABEL SUM(C) 'JORNADAS' "",1)"),"CATEG") -> CATEG | B1: =IFERROR(__xludf.DUMMYFUNCTION("""COMPUTED_VALUE"""),"CARGO") -> CARGO | C1: =IFERROR(__xludf.DUMMYFUNCTION("""COMPUTED_VALUE"""),"JORNADAS") -> JORNADAS | D1: GESTION | E1: REUNION | F1: DERECHO FUNCIONARIO | G1: HORAS CLINICAS
A2: =IFERROR(__xludf.DUMMYFUNCTION("""COMPUTED_VALUE"""),"CAT_A") -> CAT_A | B2: =IFERROR(__xludf.DUMMYFUNCTION("""COMPUTED_VALUE"""),"CIRUJANO DENTISTA") -> CIRUJANO DENTISTA | C2: =IFERROR(__xludf.DUMMYFUNCTION("""COMPUTED_VALUE"""),66.0) -> 66 | D2: =IFERROR(__xludf.DUMMYFUNCTION("IFERROR(INDEX(QUERY(HNCxTIPO!$A$3:$I27,""SELECT sum(E) WHERE B='""&$B2&""' "",0),2),"""")"),2.9) -> 2.9 | E2: =IFERROR(__xludf.DUMMYFUNCTION("IFERROR(INDEX(QUERY(HNCxTIPO!$A$3:$I27,""SELECT sum(F) WHERE B='""&$B2&""' "",0),2),"""")"),2.2) -> 2.2 | F2: =IFERROR(__xludf.DUMMYFUNCTION("IFERROR(INDEX(QUERY(HNCxTIPO!$A$3:$I27,""SELECT sum(G) WHERE B='""&$B2&""' "",0),2),"""")"),7.41) -> 7.41 | G2: =C2-D2-E2-F2 -> 53.49
A3: =IFERROR(__xludf.DUMMYFUNCTION("""COMPUTED_VALUE"""),"CAT_A") -> CAT_A | B3: =IFERROR(__xludf.DUMMYFUNCTION("""COMPUTED_VALUE"""),"MEDICO CIRUJANO") -> MEDICO CIRUJANO | C3: =IFERROR(__xludf.DUMMYFUNCTION("""COMPUTED_VALUE"""),88.0) -> 88 | D3: =IFERROR(__xludf.DUMMYFUNCTION("IFERROR(INDEX(QUERY(HNCxTIPO!$A$3:$I27,""SELECT sum(E) WHERE B='""&$B3&""' "",0),2),"""")"),6.05) -> 6.05 | E3: =IFERROR(__xludf.DUMMYFUNCTION("IFERROR(INDEX(QUERY(HNCxTIPO!$A$3:$I27,""SELECT sum(F) WHERE B='""&$B3&""' "",0),2),"""")"),4.4) -> 4.4 | F3: =IFERROR(__xludf.DUMMYFUNCTION("IFERROR(INDEX(QUERY(HNCxTIPO!$A$3:$I27,""SELECT sum(G) WHERE B='""&$B3&""' "",0),2),"""")"),12.5) -> 12.5 | G3: =C3-D3-E3-F3 -> 65.05
A4: =IFERROR(__xludf.DUMMYFUNCTION("""COMPUTED_VALUE"""),"CAT_B") -> CAT_B | B4: =IFERROR(__xludf.DUMMYFUNCTION("""COMPUTED_VALUE"""),"ENFERMERA(O)") -> ENFERMERA(O) | C4: =IFERROR(__xludf.DUMMYFUNCTION("""COMPUTED_VALUE"""),66.0) -> 66 | D4: =IFERROR(__xludf.DUMMYFUNCTION("IFERROR(INDEX(QUERY(HNCxTIPO!$A$3:$I27,""SELECT sum(E) WHERE B='""&$B4&""' "",0),2),"""")"),27.4) -> 27.4 | E4: =IFERROR(__xludf.DUMMYFUNCTION("IFERROR(INDEX(QUERY(HNCxTIPO!$A$3:$I27,""SELECT sum(F) WHERE B='""&$B4&""' "",0),2),"""")"),2.2) -> 2.2 | F4: =IFERROR(__xludf.DUMMYFUNCTION("IFERROR(INDEX(QUERY(HNCxTIPO!$A$3:$I27,""SELECT sum(G) WHERE B='""&$B4&""' "",0),2),"""")"),8.75) -> 8.75 | G4: =C4-D4-E4-F4 -> 27.65
A5: =IFERROR(__xludf.DUMMYFUNCTION("""COMPUTED_VALUE"""),"CAT_B") -> CAT_B | B5: =IFERROR(__xludf.DUMMYFUNCTION("""COMPUTED_VALUE"""),"GESTOR COMUNITARIO") -> GESTOR COMUNITARIO | C5: =IFERROR(__xludf.DUMMYFUNCTION("""COMPUTED_VALUE"""),33.0) -> 33 | D5: =IFERROR(__xludf.DUMMYFUNCTION("IFERROR(INDEX(QUERY(HNCxTIPO!$A$3:$I27,""SELECT sum(E) WHERE B='""&$B5&""' "",0),2),"""")"),33.9) -> 33.9 | E5: =IFERROR(__xludf.DUMMYFUNCTION("IFERROR(INDEX(QUERY(HNCxTIPO!$A$3:$I27,""SELECT sum(F) WHERE B='""&$B5&""' "",0),2),"""")"),2.2) -> 2.2 | F5: =IFERROR(__xludf.DUMMYFUNCTION("IFERROR(INDEX(QUERY(HNCxTIPO!$A$3:$I27,""SELECT sum(G) WHERE B='""&$B5&""' "",0),2),"""")"),6.25) -> 6.25 | G5: =C5-D5-E5-F5 -> -9.35
A6: =IFERROR(__xludf.DUMMYFUNCTION("""COMPUTED_VALUE"""),"CAT_B") -> CAT_B | B6: =IFERROR(__xludf.DUMMYFUNCTION("""COMPUTED_VALUE"""),"KINESIOLOGA/O") -> KINESIOLOGA/O | C6: =IFERROR(__xludf.DUMMYFUNCTION("""COMPUTED_VALUE"""),44.0) -> 44 | D6: =IFERROR(__xludf.DUMMYFUNCTION("IFERROR(INDEX(QUERY(HNCxTIPO!$A$3:$I27,""SELECT sum(E) WHERE B='""&$B6&""' "",0),2),"""")"),8.0) -> 8 | E6: =IFERROR(__xludf.DUMMYFUNCTION("IFERROR(INDEX(QUERY(HNCxTIPO!$A$3:$I27,""SELECT sum(F) WHERE B='""&$B6&""' "",0),2),"""")"),2.2) -> 2.2 | F6: =IFERROR(__xludf.DUMMYFUNCTION("IFERROR(INDEX(QUERY(HNCxTIPO!$A$3:$I27,""SELECT sum(G) WHERE B='""&$B6&""' "",0),2),"""")"),6.66) -> 6.66 | G6: =C6-D6-E6-F6 -> 27.14
A7: =IFERROR(__xludf.DUMMYFUNCTION("""COMPUTED_VALUE"""),"CAT_B") -> CAT_B | B7: =IFERROR(__xludf.DUMMYFUNCTION("""COMPUTED_VALUE"""),"MATRON/A") -> MATRON/A | C7: =IFERROR(__xludf.DUMMYFUNCTION("""COMPUTED_VALUE"""),44.0) -> 44 | D7: =IFERROR(__xludf.DUMMYFUNCTION("IFERROR(INDEX(QUERY(HNCxTIPO!$A$3:$I27,""SELECT sum(E) WHERE B='""&$B7&""' "",0),2),"""")"),17.0) -> 17 | E7: =IFERROR(__xludf.DUMMYFUNCTION("IFERROR(INDEX(QUERY(HNCxTIPO!$A$3:$I27,""SELECT sum(F) WHERE B='""&$B7&""' "",0),2),"""")"),1.6) -> 1.6 | F7: =IFERROR(__xludf.DUMMYFUNCTION("IFERROR(INDEX(QUERY(HNCxTIPO!$A$3:$I27,""SELECT sum(G) WHERE B='""&$B7&""' "",0),2),"""")"),6.66) -> 6.66 | G7: =C7-D7-E7-F7 -> 18.74
A8: =IFERROR(__xludf.DUMMYFUNCTION("""COMPUTED_VALUE"""),"CAT_B") -> CAT_B | B8: =IFERROR(__xludf.DUMMYFUNCTION("""COMPUTED_VALUE"""),"NUTRICIONISTA") -> NUTRICIONISTA | C8: =IFERROR(__xludf.DUMMYFUNCTION("""COMPUTED_VALUE"""),44.0) -> 44 | D8: =IFERROR(__xludf.DUMMYFUNCTION("IFERROR(INDEX(QUERY(HNCxTIPO!$A$3:$I27,""SELECT sum(E) WHERE B='""&$B8&""' "",0),2),"""")"),24.0) -> 24 | E8: =IFERROR(__xludf.DUMMYFUNCTION("IFERROR(INDEX(QUERY(HNCxTIPO!$A$3:$I27,""SELECT sum(F) WHERE B='""&$B8&""' "",0),2),"""")"),2.2) -> 2.2 | F8: =IFERROR(__xludf.DUMMYFUNCTION("IFERROR(INDEX(QUERY(HNCxTIPO!$A$3:$I27,""SELECT sum(G) WHERE B='""&$B8&""' "",0),2),"""")"),6.25) -> 6.25 | G8: =C8-D8-E8-F8 -> 11.55
A9: =IFERROR(__xludf.DUMMYFUNCTION("""COMPUTED_VALUE"""),"CAT_B") -> CAT_B | B9: =IFERROR(__xludf.DUMMYFUNCTION("""COMPUTED_VALUE"""),"PSICOLOGA/O") -> PSICOLOGA/O | C9: =IFERROR(__xludf.DUMMYFUNCTION("""COMPUTED_VALUE"""),44.0) -> 44 | D9: =IFERROR(__xludf.DUMMYFUNCTION("IFERROR(INDEX(QUERY(HNCxTIPO!$A$3:$I27,""SELECT sum(E) WHERE B='""&$B9&""' "",0),2),"""")"),1.8) -> 1.8 | E9: =IFERROR(__xludf.DUMMYFUNCTION("IFERROR(INDEX(QUERY(HNCxTIPO!$A$3:$I27,""SELECT sum(F) WHERE B='""&$B9&""' "",0),2),"""")"),2.2) -> 2.2 | F9: =IFERROR(__xludf.DUMMYFUNCTION("IFERROR(INDEX(QUERY(HNCxTIPO!$A$3:$I27,""SELECT sum(G) WHERE B='""&$B9&""' "",0),2),"""")"),5.75) -> 5.75 | G9: =C9-D9-E9-F9 -> 34.25
A10: =IFERROR(__xludf.DUMMYFUNCTION("""COMPUTED_VALUE"""),"CAT_B") -> CAT_B | B10: =IFERROR(__xludf.DUMMYFUNCTION("""COMPUTED_VALUE"""),"TRABAJADOR/A SOCIAL") -> TRABAJADOR/A SOCIAL | C10: =IFERROR(__xludf.DUMMYFUNCTION("""COMPUTED_VALUE"""),88.0) -> 88 | D10: =IFERROR(__xludf.DUMMYFUNCTION("IFERROR(INDEX(QUERY(HNCxTIPO!$A$3:$I27,""SELECT sum(E) WHERE B='""&$B10&""' "",0),2),"""")"),23.799999999999997) -> 23.8 | E10: =IFERROR(__xludf.DUMMYFUNCTION("IFERROR(INDEX(QUERY(HNCxTIPO!$A$3:$I27,""SELECT sum(F) WHERE B='""&$B10&""' "",0),2),"""")"),2.2) -> 2.2 | F10: =IFERROR(__xludf.DUMMYFUNCTION("IFERROR(INDEX(QUERY(HNCxTIPO!$A$3:$I27,""SELECT sum(G) WHERE B='""&$B10&""' "",0),2),"""")"),34.5) -> 34.5 | G10: =C10-D10-E10-F10 -> 27.5
A11: =IFERROR(__xludf.DUMMYFUNCTION("""COMPUTED_VALUE"""),"CAT_C") -> CAT_C | B11: =IFERROR(__xludf.DUMMYFUNCTION("""COMPUTED_VALUE"""),"PODOLOGA") -> PODOLOGA | C11: =IFERROR(__xludf.DUMMYFUNCTION("""COMPUTED_VALUE"""),22.0) -> 22 | D11: =IFERROR(__xludf.DUMMYFUNCTION("IFERROR(INDEX(QUERY(HNCxTIPO!$A$3:$I27,""SELECT sum(E) WHERE B='""&$B11&""' "",0),2),"""")"),0.9) -> 0.9 | E11: =IFERROR(__xludf.DUMMYFUNCTION("IFERROR(INDEX(QUERY(HNCxTIPO!$A$3:$I27,""SELECT sum(F) WHERE B='""&$B11&""' "",0),2),"""")"),"") | F11: =IFERROR(__xludf.DUMMYFUNCTION("IFERROR(INDEX(QUERY(HNCxTIPO!$A$3:$I27,""SELECT sum(G) WHERE B='""&$B11&""' "",0),2),"""")"),2.5) -> 2.5 | G11: =C11-D11-E11-F11 -> 18.6
A12: =IFERROR(__xludf.DUMMYFUNCTION("""COMPUTED_VALUE"""),"CAT_C") -> CAT_C | B12: =IFERROR(__xludf.DUMMYFUNCTION("""COMPUTED_VALUE"""),"TENS") -> TENS | C12: =IFERROR(__xludf.DUMMYFUNCTION("""COMPUTED_VALUE"""),132.0) -> 132 | D12: =IFERROR(__xludf.DUMMYFUNCTION("IFERROR(INDEX(QUERY(HNCxTIPO!$A$3:$I27,""SELECT sum(E) WHERE B='""&$B12&""' "",0),2),"""")"),6.0) -> 6 | E12: =IFERROR(__xludf.DUMMYFUNCTION("IFERROR(INDEX(QUERY(HNCxTIPO!$A$3:$I27,""SELECT sum(F) WHERE B='""&$B12&""' "",0),2),"""")"),6.6000000000000005) -> 6.6 | F12: =IFERROR(__xludf.DUMMYFUNCTION("IFERROR(INDEX(QUERY(HNCxTIPO!$A$3:$I27,""SELECT sum(G) WHERE B='""&$B12&""' "",0),2),"""")"),18.75) -> 18.75 | G12: =C12-D12-E12-F12 -> 100.65
A13: =IFERROR(__xludf.DUMMYFUNCTION("""COMPUTED_VALUE"""),"CAT_C") -> CAT_C | B13: =IFERROR(__xludf.DUMMYFUNCTION("""COMPUTED_VALUE"""),"TENS FARMACIA") -> TENS FARMACIA | C13: =IFERROR(__xludf.DUMMYFUNCTION("""COMPUTED_VALUE"""),44.0) -> 44 | D13: =IFERROR(__xludf.DUMMYFUNCTION("IFERROR(INDEX(QUERY(HNCxTIPO!$A$3:$I27,""SELECT sum(E) WHERE B='""&$B13&""' "",0),2),"""")"),2.0) -> 2 | E13: =IFERROR(__xludf.DUMMYFUNCTION("IFERROR(INDEX(QUERY(HNCxTIPO!$A$3:$I27,""SELECT sum(F) WHERE B='""&$B13&""' "",0),2),"""")"),2.2) -> 2.2 | F13: =IFERROR(__xludf.DUMMYFUNCTION("IFERROR(INDEX(QUERY(HNCxTIPO!$A$3:$I27,""SELECT sum(G) WHERE B='""&$B13&""' "",0),2),"""")"),6.25) -> 6.25 | G13: =C13-D13-E13-F13 -> 33.55
A14: =IFERROR(__xludf.DUMMYFUNCTION("""COMPUTED_VALUE"""),"CAT_C") -> CAT_C | B14: =IFERROR(__xludf.DUMMYFUNCTION("""COMPUTED_VALUE"""),"TONS") -> TONS | C14: =IFERROR(__xludf.DUMMYFUNCTION("""COMPUTED_VALUE"""),44.0) -> 44

Sheet RESUMEN_HNCxTIPO_porcent
A1: =IFERROR(__xludf.DUMMYFUNCTION("QUERY(HNCxTIPO!A3:I1000,""SELECT A,B,SUM(C) WHERE B IS NOT NULL GROUP BY A,B LABEL SUM(C) 'JORNADAS' "",1)"),"CATEG") -> CATEG | B1: =IFERROR(__xludf.DUMMYFUNCTION("""COMPUTED_VALUE"""),"CARGO") -> CARGO | C1: =IFERROR(__xludf.DUMMYFUNCTION("""COMPUTED_VALUE"""),"JORNADAS") -> JORNADAS | D1: GESTION | E1: REUNION | F1: DERECHO FUNCIONARIO
A2: =IFERROR(__xludf.DUMMYFUNCTION("""COMPUTED_VALUE"""),"CAT_A") -> CAT_A | B2: =IFERROR(__xludf.DUMMYFUNCTION("""COMPUTED_VALUE"""),"CIRUJANO DENTISTA") -> CIRUJANO DENTISTA | C2: =IFERROR(__xludf.DUMMYFUNCTION("""COMPUTED_VALUE"""),66.0) -> 66 | D2: =IFERROR(__xludf.DUMMYFUNCTION("IFERROR(INDEX(QUERY(HNCxTIPO!$A$3:$I27,""SELECT sum(E)/SUM(H) WHERE B='""&$B2&""' "",0),2),"""")"),0.23181454836131093) -> 0.23181455 | E2: =IFERROR(__xludf.DUMMYFUNCTION("IFERROR(INDEX(QUERY(HNCxTIPO!$A$3:$I27,""SELECT sum(F)/SUM(H) WHERE B='""&$B2&""' "",0),2),"""")"),0.17585931254996004) -> 0.17585931 | F2: =IFERROR(__xludf.DUMMYFUNCTION("IFERROR(INDEX(QUERY(HNCxTIPO!$A$3:$I27,""SELECT sum(G)/SUM(H) WHERE B='""&$B2&""' "",0),2),"""")"),0.592326139088729) -> 0.59232614
A3: =IFERROR(__xludf.DUMMYFUNCTION("""COMPUTED_VALUE"""),"CAT_A") -> CAT_A | B3: =IFERROR(__xludf.DUMMYFUNCTION("""COMPUTED_VALUE"""),"MEDICO CIRUJANO") -> MEDICO CIRUJANO | C3: =IFERROR(__xludf.DUMMYFUNCTION("""COMPUTED_VALUE"""),88.0) -> 88 | D3: =IFERROR(__xludf.DUMMYFUNCTION("IFERROR(INDEX(QUERY(HNCxTIPO!$A$3:$I27,""SELECT sum(E)/SUM(H) WHERE B='""&$B3&""' "",0),2),"""")"),0.2636165577342048) -> 0.26361656 | E3: =IFERROR(__xludf.DUMMYFUNCTION("IFERROR(INDEX(QUERY(HNCxTIPO!$A$3:$I27,""SELECT sum(F)/SUM(H) WHERE B='""&$B3&""' "",0),2),"""")"),0.1917211328976035) -> 0.19172113 | F3: =IFERROR(__xludf.DUMMYFUNCTION("IFERROR(INDEX(QUERY(HNCxTIPO!$A$3:$I27,""SELECT sum(G)/SUM(H) WHERE B='""&$B3&""' "",0),2),"""")"),0.5446623093681917) -> 0.54466231
A4: =IFERROR(__xludf.DUMMYFUNCTION("""COMPUTED_VALUE"""),"CAT_B") -> CAT_B | B4: =IFERROR(__xludf.DUMMYFUNCTION("""COMPUTED_VALUE"""),"ENFERMERA(O)") -> ENFERMERA(O) | C4: =IFERROR(__xludf.DUMMYFUNCTION("""COMPUTED_VALUE"""),66.0) -> 66 | D4: =IFERROR(__xludf.DUMMYFUNCTION("IFERROR(INDEX(QUERY(HNCxTIPO!$A$3:$I27,""SELECT sum(E)/SUM(H) WHERE B='""&$B4&""' "",0),2),"""")"),0.7144719687092568) -> 0.71447197 | E4: =IFERROR(__xludf.DUMMYFUNCTION("IFERROR(INDEX(QUERY(HNCxTIPO!$A$3:$I27,""SELECT sum(F)/SUM(H) WHERE B='""&$B4&""' "",0),2),"""")"),0.05736636245110822) -> 0.057366362 | F4: =IFERROR(__xludf.DUMMYFUNCTION("IFERROR(INDEX(QUERY(HNCxTIPO!$A$3:$I27,""SELECT sum(G)/SUM(H) WHERE B='""&$B4&""' "",0),2),"""")"),0.22816166883963493) -> 0.22816167
A5: =IFERROR(__xludf.DUMMYFUNCTION("""COMPUTED_VALUE"""),"CAT_B") -> CAT_B | B5: =IFERROR(__xludf.DUMMYFUNCTION("""COMPUTED_VALUE"""),"GESTOR COMUNITARIO") -> GESTOR COMUNITARIO | C5: =IFERROR(__xludf.DUMMYFUNCTION("""COMPUTED_VALUE"""),33.0) -> 33 | D5: =IFERROR(__xludf.DUMMYFUNCTION("IFERROR(INDEX(QUERY(HNCxTIPO!$A$3:$I27,""SELECT sum(E)/SUM(H) WHERE B='""&$B5&""' "",0),2),"""")"),0.8004722550177095) -> 0.80047225 | E5: =IFERROR(__xludf.DUMMYFUNCTION("IFERROR(INDEX(QUERY(HNCxTIPO!$A$3:$I27,""SELECT sum(F)/SUM(H) WHERE B='""&$B5&""' "",0),2),"""")"),0.05194805194805195) -> 0.051948052 | F5: =IFERROR(__xludf.DUMMYFUNCTION("IFERROR(INDEX(QUERY(HNCxTIPO!$A$3:$I27,""SELECT sum(G)/SUM(H) WHERE B='""&$B5&""' "",0),2),"""")"),0.14757969303423848) -> 0.14757969
A6: =IFERROR(__xludf.DUMMYFUNCTION("""COMPUTED_VALUE"""),"CAT_B") -> CAT_B | B6: =IFERROR(__xludf.DUMMYFUNCTION("""COMPUTED_VALUE"""),"KINESIOLOGA/O") -> KINESIOLOGA/O | C6: =IFERROR(__xludf.DUMMYFUNCTION("""COMPUTED_VALUE"""),44.0) -> 44 | D6: =IFERROR(__xludf.DUMMYFUNCTION("IFERROR(INDEX(QUERY(HNCxTIPO!$A$3:$I27,""SELECT sum(E)/SUM(H) WHERE B='""&$B6&""' "",0),2),"""")"),0.4744958481613286) -> 0.47449585 | E6: =IFERROR(__xludf.DUMMYFUNCTION("IFERROR(INDEX(QUERY(HNCxTIPO!$A$3:$I27,""SELECT sum(F)/SUM(H) WHERE B='""&$B6&""' "",0),2),"""")"),0.13048635824436539) -> 0.13048636 | F6: =IFERROR(__xludf.DUMMYFUNCTION("IFERROR(INDEX(QUERY(HNCxTIPO!$A$3:$I27,""SELECT sum(G)/SUM(H) WHERE B='""&$B6&""' "",0),2),"""")"),0.39501779359430605) -> 0.39501779
A7: =IFERROR(__xludf.DUMMYFUNCTION("""COMPUTED_VALUE"""),"CAT_B") -> CAT_B | B7: =IFERROR(__xludf.DUMMYFUNCTION("""COMPUTED_VALUE"""),"MATRON/A") -> MATRON/A | C7: =IFERROR(__xludf.DUMMYFUNCTION("""COMPUTED_VALUE"""),44.0) -> 44 | D7: =IFERROR(__xludf.DUMMYFUNCTION("IFERROR(INDEX(QUERY(HNCxTIPO!$A$3:$I27,""SELECT sum(E)/SUM(H) WHERE B='""&$B7&""' "",0),2),"""")"),0.6730007917656373) -> 0.67300079 | E7: =IFERROR(__xludf.DUMMYFUNCTION("IFERROR(INDEX(QUERY(HNCxTIPO!$A$3:$I27,""SELECT sum(F)/SUM(H) WHERE B='""&$B7&""' "",0),2),"""")"),0.06334125098970704) -> 0.063341251 | F7: =IFERROR(__xludf.DUMMYFUNCTION("IFERROR(INDEX(QUERY(HNCxTIPO!$A$3:$I27,""SELECT sum(G)/SUM(H) WHERE B='""&$B7&""' "",0),2),"""")"),0.26365795724465557) -> 0.26365796
A8: =IFERROR(__xludf.DUMMYFUNCTION("""COMPUTED_VALUE"""),"CAT_B") -> CAT_B | B8: =IFERROR(__xludf.DUMMYFUNCTION("""COMPUTED_VALUE"""),"NUTRICIONISTA") -> NUTRICIONISTA | C8: =IFERROR(__xludf.DUMMYFUNCTION("""COMPUTED_VALUE"""),44.0) -> 44 | D8: =IFERROR(__xludf.DUMMYFUNCTION("IFERROR(INDEX(QUERY(HNCxTIPO!$A$3:$I27,""SELECT sum(E)/SUM(H) WHERE B='""&$B8&""' "",0),2),"""")"),0.7395993836671803) -> 0.73959938 | E8: =IFERROR(__xludf.DUMMYFUNCTION("IFERROR(INDEX(QUERY(HNCxTIPO!$A$3:$I27,""SELECT sum(F)/SUM(H) WHERE B='""&$B8&""' "",0),2),"""")"),0.06779661016949153) -> 0.06779661 | F8: =IFERROR(__xludf.DUMMYFUNCTION("IFERROR(INDEX(QUERY(HNCxTIPO!$A$3:$I27,""SELECT sum(G)/SUM(H) WHERE B='""&$B8&""' "",0),2),"""")"),0.19260400616332818) -> 0.19260401
A9: =IFERROR(__xludf.DUMMYFUNCTION("""COMPUTED_VALUE"""),"CAT_B") -> CAT_B | B9: =IFERROR(__xludf.DUMMYFUNCTION("""COMPUTED_VALUE"""),"PSICOLOGA/O") -> PSICOLOGA/O | C9: =IFERROR(__xludf.DUMMYFUNCTION("""COMPUTED_VALUE"""),44.0) -> 44 | D9: =IFERROR(__xludf.DUMMYFUNCTION("IFERROR(INDEX(QUERY(HNCxTIPO!$A$3:$I27,""SELECT sum(E)/SUM(H) WHERE B='""&$B9&""' "",0),2),"""")"),0.18461538461538463) -> 0.18461538 | E9: =IFERROR(__xludf.DUMMYFUNCTION("IFERROR(INDEX(QUERY(HNCxTIPO!$A$3:$I27,""SELECT sum(F)/SUM(H) WHERE B='""&$B9&""' "",0),2),"""")"),0.22564102564102567) -> 0.22564103 | F9: =IFERROR(__xludf.DUMMYFUNCTION("IFERROR(INDEX(QUERY(HNCxTIPO!$A$3:$I27,""SELECT sum(G)/SUM(H) WHERE B='""&$B9&""' "",0),2),"""")"),0.5897435897435898) -> 0.58974359
A10: =IFERROR(__xludf.DUMMYFUNCTION("""COMPUTED_VALUE"""),"CAT_B") -> CAT_B | B10: =IFERROR(__xludf.DUMMYFUNCTION("""COMPUTED_VALUE"""),"TRABAJADOR/A SOCIAL") -> TRABAJADOR/A SOCIAL | C10: =IFERROR(__xludf.DUMMYFUNCTION("""COMPUTED_VALUE"""),88.0) -> 88 | D10: =IFERROR(__xludf.DUMMYFUNCTION("IFERROR(INDEX(QUERY(HNCxTIPO!$A$3:$I27,""SELECT sum(E)/SUM(H) WHERE B='""&$B10&""' "",0),2),"""")"),0.39338842975206606) -> 0.39338843 | E10: =IFERROR(__xludf.DUMMYFUNCTION("IFERROR(INDEX(QUERY(HNCxTIPO!$A$3:$I27,""SELECT sum(F)/SUM(H) WHERE B='""&$B10&""' "",0),2),"""")"),0.03636363636363637) -> 0.036363636 | F10: =IFERROR(__xludf.DUMMYFUNCTION("IFERROR(INDEX(QUERY(HNCxTIPO!$A$3:$I27,""SELECT sum(G)/SUM(H) WHERE B='""&$B10&""' "",0),2),"""")"),0.5702479338842975) -> 0.57024793
A11: =IFERROR(__xludf.DUMMYFUNCTION("""COMPUTED_VALUE"""),"CAT_C") -> CAT_C | B11: =IFERROR(__xludf.DUMMYFUNCTION("""COMPUTED_VALUE"""),"PODOLOGA") -> PODOLOGA | C11: =IFERROR(__xludf.DUMMYFUNCTION("""COMPUTED_VALUE"""),22.0) -> 22 | D11: =IFERROR(__xludf.DUMMYFUNCTION("IFERROR(INDEX(QUERY(HNCxTIPO!$A$3:$I27,""SELECT sum(E)/SUM(H) WHERE B='""&$B11&""' "",0),2),"""")"),0.2647058823529412) -> 0.26470588 | E11: =IFERROR(__xludf.DUMMYFUNCTION("IFERROR(INDEX(QUERY(HNCxTIPO!$A$3:$I27,""SELECT sum(F)/SUM(H) WHERE B='""&$B11&""' "",0),2),"""")"),"") | F11: =IFERROR(__xludf.DUMMYFUNCTION("IFERROR(INDEX(QUERY(HNCxTIPO!$A$3:$I27,""SELECT sum(G)/SUM(H) WHERE B='""&$B11&""' "",0),2),"""")"),0.7352941176470589) -> 0.73529412
A12: =IFERROR(__xludf.DUMMYFUNCTION("""COMPUTED_VALUE"""),"CAT_C") -> CAT_C | B12: =IFERROR(__xludf.DUMMYFUNCTION("""COMPUTED_VALUE"""),"TENS") -> TENS | C12: =IFERROR(__xludf.DUMMYFUNCTION("""COMPUTED_VALUE"""),132.0) -> 132 | D12: =IFERROR(__xludf.DUMMYFUNCTION("IFERROR(INDEX(QUERY(HNCxTIPO!$A$3:$I27,""SELECT sum(E)/SUM(H) WHERE B='""&$B12&""' "",0),2),"""")"),0.19138755980861244) -> 0.19138756 | E12: =IFERROR(__xludf.DUMMYFUNCTION("IFERROR(INDEX(QUERY(HNCxTIPO!$A$3:$I27,""SELECT sum(F)/SUM(H) WHERE B='""&$B12&""' "",0),2),"""")"),0.21052631578947373) -> 0.21052632 | F12: =IFERROR(__xludf.DUMMYFUNCTION("IFERROR(INDEX(QUERY(HNCxTIPO!$A$3:$I27,""SELECT sum(G)/SUM(H) WHERE B='""&$B12&""' "",0),2),"""")"),0.5980861244019139) -> 0.59808612
A13: =IFERROR(__xludf.DUMMYFUNCTION("""COMPUTED_VALUE"""),"CAT_C") -> CAT_C | B13: =IFERROR(__xludf.DUMMYFUNCTION("""COMPUTED_VALUE"""),"TENS FARMACIA") -> TENS FARMACIA | C13: =IFERROR(__xludf.DUMMYFUNCTION("""COMPUTED_VALUE"""),44.0) -> 44 | D13: =IFERROR(__xludf.DUMMYFUNCTION("IFERROR(INDEX(QUERY(HNCxTIPO!$A$3:$I27,""SELECT sum(E)/SUM(H) WHERE B='""&$B13&""' "",0),2),"""")"),0.19138755980861244) -> 0.19138756 | E13: =IFERROR(__xludf.DUMMYFUNCTION("IFERROR(INDEX(QUERY(HNCxTIPO!$A$3:$I27,""SELECT sum(F)/SUM(H) WHERE B='""&$B13&""' "",0),2),"""")"),0.21052631578947373) -> 0.21052632 | F13: =IFERROR(__xludf.DUMMYFUNCTION("IFERROR(INDEX(QUERY(HNCxTIPO!$A$3:$I27,""SELECT sum(G)/SUM(H) WHERE B='""&$B13&""' "",0),2),"""")"),0.5980861244019139) -> 0.59808612
A14: =IFERROR(__xludf.DUMMYFUNCTION("""COMPUTED_VALUE"""),"CAT_C") -> CAT_C | B14: =IFERROR(__xludf.DUMMYFUNCTION("""COMPUTED_VALUE"""),"TONS") -> TONS | C14: =IFERROR(__xludf.DUMMYFUNCTION("""COMPUTED_VALUE"""),44.0) -> 44 | D14: =IFERROR(__xludf.DUMMYFUNCTION("IFERROR(INDEX(QUERY(HNCxTIPO!$A$3:$I27,""SELECT sum(E)/""&C14&"" WHERE B='""&$B14&""' "",0),2),"""")"),0.045454545454545456) -> 0.045454545 | E14: =IFERROR(__xludf.DUMMYFUNCTION("IFERROR(INDEX(QUERY(HNCxTIPO!$A$3:$I27,""SELECT sum(F)/""&C14&"" WHERE B='""&$B14&""' "",0),2),"""")"),0.05) -> 0.05 | F14: =IFERROR(__xludf.DUMMYFUNCTION("IFERROR(INDEX(QUERY(HNCxTIPO!$A$3:$I27,""SELECT sum(G)/""&C14&"" WHERE B='""&$B14&""' "",0),2),"""")"),0.14204545454545456) -> 0.14204545

Sheet HNCxTIPO
C1: =IFERROR(__xludf.DUMMYFUNCTION("COUNTUNIQUE(D4:D123)"),20.0) -> 20 | D1: Nro HNC obtenida de BD_ENCUESTAS = | E1: =ENCUESTA_GESTION!H1 -> 157.75 | F1: =ENCUESTA_REU!H1 -> 34.4 | G1: =ENCUESTA_DER!H1 -> 135.14
C2: =SUM(C4:C123) -> 759 | D2: Nro HNC obtenida de HNCxTIPO = | E2: =SUM(E4:E123) -> 155.75 | F2: =SUM(F4:F123) -> 32.4 | G2: =SUM(G4:G123) -> 128.48 | H2: =SUM(H4:H123) -> 316.63
A3: =IFERROR(__xludf.DUMMYFUNCTION("QUERY(FUNC!A1:E1000,""SELECT B,C,D,E WHERE B IS NOT NULL AND B MATCHES '.*CAT_A|CAT_B|CAT_C|CAT_D.*' ORDER BY B,D LABEL D 'JORNADA' "",1)"),"CATEG") -> CATEG | B3: =IFERROR(__xludf.DUMMYFUNCTION("""COMPUTED_VALUE"""),"CARGO") -> CARGO | C3: =IFERROR(__xludf.DUMMYFUNCTION("""COMPUTED_VALUE"""),"JORNADA") -> JORNADA | D3: =IFERROR(__xludf.DUMMYFUNCTION("""COMPUTED_VALUE"""),"FUNCIONARIO") -> FUNCIONARIO | E3: GESTION | F3: REUNION | G3: DERECHO FUNCIONARIO | H3: TOTAL HNC
A4: =IFERROR(__xludf.DUMMYFUNCTION("""COMPUTED_VALUE"""),"CAT_A") -> CAT_A | B4: =IFERROR(__xludf.DUMMYFUNCTION("""COMPUTED_VALUE"""),"CIRUJANO DENTISTA") -> CIRUJANO DENTISTA | C4: =IFERROR(__xludf.DUMMYFUNCTION("""COMPUTED_VALUE"""),22.0) -> 22 | D4: =IFERROR(__xludf.DUMMYFUNCTION("""COMPUTED_VALUE"""),"JAIME REYES TORO") -> JAIME REYES TORO | E4: =IFERROR(__xludf.DUMMYFUNCTION("IFERROR(INDEX(QUERY(ENCUESTA_GESTION!$A$3:$H1000,""SELECT sum(H) WHERE B='""&$D4&""' "",0),2),"""")"),2.0) -> 2 | F4: =IFERROR(__xludf.DUMMYFUNCTION("IFERROR(INDEX(QUERY(ENCUESTA_REU!$A$3:$H1000,""SELECT sum(H) WHERE B='""&$D4&""' "",0),2),"""")")," ") | G4: =IFERROR(__xludf.DUMMYFUNCTION("IFERROR(INDEX(QUERY(ENCUESTA_DER!$A$3:$H1000,""SELECT sum(H) WHERE B='""&$D4&""' "",0),2),"""")"),2.75) -> 2.75 | H4: =SUM(E4:G4) -> 4.75
A5: =IFERROR(__xludf.DUMMYFUNCTION("""COMPUTED_VALUE"""),"CAT_A") -> CAT_A | B5: =IFERROR(__xludf.DUMMYFUNCTION("""COMPUTED_VALUE"""),"MEDICO CIRUJANO") -> MEDICO CIRUJANO | C5: =IFERROR(__xludf.DUMMYFUNCTION("""COMPUTED_VALUE"""),44.0) -> 44 | D5: =IFERROR(__xludf.DUMMYFUNCTION("""COMPUTED_VALUE"""),"GERARDO VALENCIA BERMUDEZ") -> GERARDO VALENCIA BERMUDEZ | E5: =IFERROR(__xludf.DUMMYFUNCTION("IFERROR(INDEX(QUERY(ENCUESTA_GESTION!$A$3:$H1000,""SELECT sum(H) WHERE B='""&$D5&""' "",0),2),"""")"),2.15) -> 2.15 | F5: =IFERROR(__xludf.DUMMYFUNCTION("IFERROR(INDEX(QUERY(ENCUESTA_REU!$A$3:$H1000,""SELECT sum(H) WHERE B='""&$D5&""' "",0),2),"""")"),2.2) -> 2.2 | G5: =IFERROR(__xludf.DUMMYFUNCTION("IFERROR(INDEX(QUERY(ENCUESTA_DER!$A$3:$H1000,""SELECT sum(H) WHERE B='""&$D5&""' "",0),2),"""")"),6.25) -> 6.25 | H5: =SUM(E5:G5) -> 10.6
A6: =IFERROR(__xludf.DUMMYFUNCTION("""COMPUTED_VALUE"""),"CAT_A") -> CAT_A | B6: =IFERROR(__xludf.DUMMYFUNCTION("""COMPUTED_VALUE"""),"MEDICO CIRUJANO") -> MEDICO CIRUJANO | C6: =IFERROR(__xludf.DUMMYFUNCTION("""COMPUTED_VALUE"""),44.0) -> 44 | D6: =IFERROR(__xludf.DUMMYFUNCTION("""COMPUTED_VALUE"""),"CONSTANZA PALMA MONTERO") -> CONSTANZA PALMA MONTERO | E6: =IFERROR(__xludf.DUMMYFUNCTION("IFERROR(INDEX(QUERY(ENCUESTA_GESTION!$A$3:$H1000,""SELECT sum(H) WHERE B='""&$D6&""' "",0),2),"""")"),3.9) -> 3.9 | F6: =IFERROR(__xludf.DUMMYFUNCTION("IFERROR(INDEX(QUERY(ENCUESTA_REU!$A$3:$H1000,""SELECT sum(H) WHERE B='""&$D6&""' "",0),2),"""")"),2.2) -> 2.2 | G6: =IFERROR(__xludf.DUMMYFUNCTION("IFERROR(INDEX(QUERY(ENCUESTA_DER!$A$3:$H1000,""SELECT sum(H) WHERE B='""&$D6&""' "",0),2),"""")"),6.25) -> 6.25 | H6: =SUM(E6:G6) -> 12.35
A7: =IFERROR(__xludf.DUMMYFUNCTION("""COMPUTED_VALUE"""),"CAT_A") -> CAT_A | B7: =IFERROR(__xludf.DUMMYFUNCTION("""COMPUTED_VALUE"""),"CIRUJANO DENTISTA") -> CIRUJANO DENTISTA | C7: =IFERROR(__xludf.DUMMYFUNCTION("""COMPUTED_VALUE"""),44.0) -> 44 | D7: =IFERROR(__xludf.DUMMYFUNCTION("""COMPUTED_VALUE"""),"EDGAR CARVAJAL TORRES") -> EDGAR CARVAJAL TORRES | E7: =IFERROR(__xludf.DUMMYFUNCTION("IFERROR(INDEX(QUERY(ENCUESTA_GESTION!$A$3:$H1000,""SELECT sum(H) WHERE B='""&$D7&""' "",0),2),"""")"),0.9) -> 0.9 | F7: =IFERROR(__xludf.DUMMYFUNCTION("IFERROR(INDEX(QUERY(ENCUESTA_REU!$A$3:$H1000,""SELECT sum(H) WHERE B='""&$D7&""' "",0),2),"""")"),2.2) -> 2.2 | G7: =IFERROR(__xludf.DUMMYFUNCTION("IFERROR(INDEX(QUERY(ENCUESTA_DER!$A$3:$H1000,""SELECT sum(H) WHERE B='""&$D7&""' "",0),2),"""")"),4.66) -> 4.66 | H7: =SUM(E7:G7) -> 7.76
A8: =IFERROR(__xludf.DUMMYFUNCTION("""COMPUTED_VALUE"""),"CAT_B") -> CAT_B | B8: =IFERROR(__xludf.DUMMYFUNCTION("""COMPUTED_VALUE"""),"ENFERMERA(O)") -> ENFERMERA(O) | C8: =IFERROR(__xludf.DUMMYFUNCTION("""COMPUTED_VALUE"""),22.0) -> 22 | D8: =IFERROR(__xludf.DUMMYFUNCTION("""COMPUTED_VALUE"""),"FANNY QUINTANILLA CORDERO") -> FANNY QUINTANILLA CORDERO | E8: =IFERROR(__xludf.DUMMYFUNCTION("IFERROR(INDEX(QUERY(ENCUESTA_GESTION!$A$3:$H1000,""SELECT sum(H) WHERE B='""&$D8&""' "",0),2),"""")"),5.15) -> 5.15 | F8: =IFERROR(__xludf.DUMMYFUNCTION("IFERROR(INDEX(QUERY(ENCUESTA_REU!$A$3:$H1000,""SELECT sum(H) WHERE B='""&$D8&""' "",0),2),"""")")," ") | G8: =IFERROR(__xludf.DUMMYFUNCTION("IFERROR(INDEX(QUERY(ENCUESTA_DER!$A$3:$H1000,""SELECT sum(H) WHERE B='""&$D8&""' "",0),2),"""")"),2.5) -> 2.5 | H8: =SUM(E8:G8) -> 7.65
A9: =IFERROR(__xludf.DUMMYFUNCTION("""COMPUTED_VALUE"""),"CAT_B") -> CAT_B | B9: =IFERROR(__xludf.DUMMYFUNCTION("""COMPUTED_VALUE"""),"PSICOLOGA/O") -> PSICOLOGA/O | C9: =IFERROR(__xludf.DUMMYFUNCTION("""COMPUTED_VALUE"""),22.0) -> 22 | D9: =IFERROR(__xludf.DUMMYFUNCTION("""COMPUTED_VALUE"""),"CLAUDIO PINTO VILLALOBOS") -> CLAUDIO PINTO VILLALOBOS | E9: =IFERROR(__xludf.DUMMYFUNCTION("IFERROR(INDEX(QUERY(ENCUESTA_GESTION!$A$3:$H1000,""SELECT sum(H) WHERE B='""&$D9&""' "",0),2),"""")"),0.9) -> 0.9 | F9: =IFERROR(__xludf.DUMMYFUNCTION("IFERROR(INDEX(QUERY(ENCUESTA_REU!$A$3:$H1000,""SELECT sum(H) WHERE B='""&$D9&""' "",0),2),"""")"),2.2) -> 2.2 | G9: =IFERROR(__xludf.DUMMYFUNCTION("IFERROR(INDEX(QUERY(ENCUESTA_DER!$A$3:$H1000,""SELECT sum(H) WHERE B='""&$D9&""' "",0),2),"""")"),3.25) -> 3.25 | H9: =SUM(E9:G9) -> 6.35
A10: =IFERROR(__xludf.DUMMYFUNCTION("""COMPUTED_VALUE"""),"CAT_B") -> CAT_B | B10: =IFERROR(__xludf.DUMMYFUNCTION("""COMPUTED_VALUE"""),"PSICOLOGA/O") -> PSICOLOGA/O | C10: =IFERROR(__xludf.DUMMYFUNCTION("""COMPUTED_VALUE"""),22.0) -> 22 | D10: =IFERROR(__xludf.DUMMYFUNCTION("""COMPUTED_VALUE"""),"ELIZABETH ZARATE ROJAS") -> ELIZABETH ZARATE ROJAS | E10: =IFERROR(__xludf.DUMMYFUNCTION("IFERROR(INDEX(QUERY(ENCUESTA_GESTION!$A$3:$H1000,""SELECT sum(H) WHERE B='""&$D10&""' "",0),2),"""")"),0.9) -> 0.9 | F10: =IFERROR(__xludf.DUMMYFUNCTION("IFERROR(INDEX(QUERY(ENCUESTA_REU!$A$3:$H1000,""SELECT sum(H) WHERE B='""&$D10&""' "",0),2),"""")")," ") | G10: =IFERROR(__xludf.DUMMYFUNCTION("IFERROR(INDEX(QUERY(ENCUESTA_DER!$A$3:$H1000,""SELECT sum(H) WHERE B='""&$D10&""' "",0),2),"""")"),2.5) -> 2.5 | H10: =SUM(E10:G10) -> 3.4
A11: =IFERROR(__xludf.DUMMYFUNCTION("""COMPUTED_VALUE"""),"CAT_B") -> CAT_B | B11: =IFERROR(__xludf.DUMMYFUNCTION("""COMPUTED_VALUE"""),"GESTOR COMUNITARIO") -> GESTOR COMUNITARIO | C11: =IFERROR(__xludf.DUMMYFUNCTION("""COMPUTED_VALUE"""),33.0) -> 33 | D11: =IFERROR(__xludf.DUMMYFUNCTION("""COMPUTED_VALUE"""),"VANESSA ESPINOZA ESPINOZA") -> VANESSA ESPINOZA ESPINOZA | E11: =IFERROR(__xludf.DUMMYFUNCTION("IFERROR(INDEX(QUERY(ENCUESTA_GESTION!$A$3:$H1000,""SELECT sum(H) WHERE B='""&$D11&""' "",0),2),"""")"),33.9) -> 33.9 | F11: =IFERROR(__xludf.DUMMYFUNCTION("IFERROR(INDEX(QUERY(ENCUESTA_REU!$A$3:$H1000,""SELECT sum(H) WHERE B='""&$D11&""' "",0),2),"""")"),2.2) -> 2.2 | G11: =IFERROR(__xludf.DUMMYFUNCTION("IFERROR(INDEX(QUERY(ENCUESTA_DER!$A$3:$H1000,""SELECT sum(H) WHERE B='""&$D11&""' "",0),2),"""")"),6.25) -> 6.25 | H11: =SUM(E11:G11) -> 42.35
A12: =IFERROR(__xludf.DUMMYFUNCTION("""COMPUTED_VALUE"""),"CAT_B") -> CAT_B | B12: =IFERROR(__xludf.DUMMYFUNCTION("""COMPUTED_VALUE"""),"MATRON/A") -> MATRON/A | C12: =IFERROR(__xludf.DUMMYFUNCTION("""COMPUTED_VALUE"""),44.0) -> 44 | D12: =IFERROR(__xludf.DUMMYFUNCTION("""COMPUTED_VALUE"""),"SORAYA CRUCES DIAZ") -> SORAYA CRUCES DIAZ | E12: =IFERROR(__xludf.DUMMYFUNCTION("IFERROR(INDEX(QUERY(ENCUESTA_GESTION!$A$3:$H1000,""SELECT sum(H) WHERE B='""&$D12&""' "",0),2),"""")"),17.0) -> 17 | F12: =IFERROR(__xludf.DUMMYFUNCTION("IFERROR(INDEX(QUERY(ENCUESTA_REU!$A$3:$H1000,""SELECT sum(H) WHERE B='""&$D12&""' "",0),2),"""")"),1.6) -> 1.6 | G12: =IFERROR(__xludf.DUMMYFUNCTION("IFERROR(INDEX(QUERY(ENCUESTA_DER!$A$3:$H1000,""SELECT sum(H) WHERE B='""&$D12&""' "",0),2),"""")"),6.66) -> 6.66 | H12: =SUM(E12:G12) -> 25.26
A13: =IFERROR(__xludf.DUMMYFUNCTION("""COMPUTED_VALUE"""),"CAT_B") -> CAT_B | B13: =IFERROR(__xludf.DUMMYFUNCTION("""COMPUTED_VALUE"""),"KINESIOLOGA/O") -> KINESIOLOGA/O | C13: =IFERROR(__xludf.DUMMYFUNCTION("""COMPUTED_VALUE"""),44.0) -> 44 | D13: =IFERROR(__xludf.DUMMYFUNCTION("""COMPUTED_VALUE"""),"ALEJANDRO REYES MURILLO") -> ALEJANDRO REYES MURILLO | E13: =IFERROR(__xludf.DUMMYFUNCTION("IFERROR(INDEX(QUERY(ENCUESTA_GESTION!$A$3:$H1000,""SELECT sum(H) WHERE B='""&$D13&""' "",0),2),"""")"),8.0) -> 8 | F13: =IFERROR(__xludf.DUMMYFUNCTION("IFERROR(INDEX(QUERY(ENCUESTA_REU!$A$3:$H1000,""SELECT sum(H) WHERE B='""&$D13&""' "",0),2),"""")"),2.2) -> 2.2 | G13: =IFERROR(__xludf.DUMMYFUNCTION("IFERROR(INDEX(QUERY(ENCUESTA_DER!$A$3:$H1000,""SELECT sum(H) WHERE B='""&$D13&""' "",0),2),"""")"),6.66) -> 6.66 | H13: =SUM(E13:G13) -> 16.86
A14: =IFERROR(__xludf.DUMMYFUNCTION("""COMPUTED_VALUE"""),"CAT_B") -> CAT_B | B14: =IFERROR(__xludf.DUMMYFUNCTION("""COMPUTED_VALUE"""),"TRABAJADOR/A SOCIAL") -> TRABAJADOR/A SOCIAL | C14: =IFERROR(__xludf.DUMMYFUNCTION("""COMPUTED_VALUE"""),44.0) -> 44 | D14: =IFERROR(__xludf.DUMMYFUNCTION("""COMPUTED_VALUE"""),"MARCELA JAQUE LIZAMA") -> MARCELA JAQUE LIZAMA | E14: =IFERROR(__xludf.DUMMYFUNCTION("IFERROR(INDEX(QUERY(ENCUESTA_GESTION!$A$3:$H1000,""SELECT sum(H) WHERE B='""&$D14&""' "",0),2),"""")"),0.9) -> 0.9 | F14: =IFERROR(__xludf.DUMMYFUNCTION("IFERROR(INDEX(QUERY(ENCUESTA_REU!$A$3:$H1000,""SELECT sum(H) WHERE B='""&$D14&""' "",0),2),"""")")," ") | G14: =IFERROR(__xludf.DUMMYFUNCTION("IFERROR(INDEX(QUERY(ENCUESTA_DER!$A$3:$H1000,""SELECT sum(H) WHERE B='""&$D14&""' "",0),2),"""")"),28.25) -> 28.25 | H14: =SUM(E14:G14) -> 29.15
A15: =IFERROR(__xludf.DUMMYFUNCTION("""COMPUTED_VALUE"""),"CAT_B") -> CAT_B | B15: =IFERROR(__xludf.DUMMYFUNCTION("""COMPUTED_VALUE"""),"TRABAJADOR/A SOCIAL") -> TRABAJADOR/A SOCIAL | C15: =IFERROR(__xludf.DUMMYFUNCTION("""COMPUTED_VALUE"""),44.0) -> 44 | D15: =IFERROR(__xludf.DUMMYFUNCTION("""COMPUTED_VALUE"""),"PAULINA DIAZ MEDINA") -> PAULINA DIAZ MEDINA | E15: =IFERROR(__xludf.DUMMYFUNCTION("IFERROR(INDEX(QUERY(ENCUESTA_GESTION!$A$3:$H1000,""SELECT sum(H) WHERE B='""&$D15&""' "",0),2),"""")"),22.9) -> 22.9 | F15: =IFERROR(__xludf.DUMMYFUNCTION("IFERROR(INDEX(QUERY(ENCUESTA_REU!$A$3:$H1000,""SELECT sum(H) WHERE B='""&$D15&""' "",0),2),"""")"),2.2) -> 2.2 | G15: =IFERROR(__xludf.DUMMYFUNCTION("IFERROR(INDEX(QUERY(ENCUESTA_DER!$A$3:$H1000,""SELECT sum(H) WHERE B='""&$D15&""' "",0),2),"""")"),6.25) -> 6.25 | H15: =SUM(E15:G15) -> 31.35
A16: =IFERROR(__xludf.DUMMYFUNCTION("""COMPUTED_VALUE"""),"CAT_B") -> CAT_B | B16: =IFERROR(__xludf.DUMMYFUNCTION("""COMPUTED_VALUE"""),"ENFERMERA(O)") -> ENFERMERA(O) | C16: =IFERROR(__xludf.DUMMYFUNCTION("""COMPUTED_VALUE"""),44.0) -> 44 | D16: =IFERROR(__xludf.DUMMYFUNCTION("""COMPUTED_VALUE"""),"CAROL AMBO AMPUERO") -> CAROL AMBO AMPUERO | E16: =IFERROR(__xludf.DUMMYFUNCTION("IFERROR(INDEX(QUERY(ENCUESTA_GESTION!$A$3:$H1000,""SELECT sum(H) WHERE B='""&$D16&""' "",0),2),"""")"),22.25) -> 22.25 | F16: =IFERROR(__xludf.DUMMYFUNCTION("IFERROR(INDEX(QUERY(ENCUESTA_REU!$A$3:$H1000,""SELECT sum(H) WHERE B='""&$D16&""' "",0),2),"""")"),2.2) -> 2.2 | G16: =IFERROR(__xludf.DUMMYFUNCTION("IFERROR(INDEX(QUERY(ENCUESTA_DER!$A$3:$H1000,""SELECT sum(H) WHERE B='""&$D16&""' "",0),2),"""")"),6.25) -> 6.25 | H16: =SUM(E16:G16) -> 30.7
A17: =IFERROR(__xludf.DUMMYFUNCTION("""COMPUTED_VALUE"""),"CAT_B") -> CAT_B | B17: =IFERROR(__xludf.DUMMYFUNCTION("""COMPUTED_VALUE"""),"NUTRICIONISTA") -> NUTRICIONISTA | C17: =IFERROR(__xludf.DUMMYFUNCTION("""COMPUTED_VALUE"""),44.0) -> 44 | D17: =IFERROR(__xludf.DUMMYFUNCTION("""COMPUTED_VALUE"""),"PAULA ABARCA MORALES") -> PAULA ABARCA MORALES | E17: =IFERROR(__xludf.DUMMYFUNCTION("IFERROR(INDEX(QUERY(ENCUESTA_GESTION!$A$3:$H1000,""SELECT sum(H) WHERE B='""&$D17&""' "",0),2),"""")"),24.0) -> 24 | F17: =IFERROR(__xludf.DUMMYFUNCTION("IFERROR(INDEX(QUERY(ENCUESTA_REU!$A$3:$H1000,""SELECT sum(H) WHERE B='""&$D17&""' "",0),2),"""")"),2.2) -> 2.2 | G17: =IFERROR(__xludf.DUMMYFUNCTION("IFERROR(INDEX(QUERY(ENCUESTA_DER!$A$3:$H1000,""SELECT sum(H) WHERE B='""&$D17&""' "",0),2),"""")"),6.25) -> 6.25 | H17: =SUM(E17:G17) -> 32.45
A18: =IFERROR(__xludf.DUMMYFUNCTION("""COMPUTED_VALUE"""),"CAT_C") -> CAT_C | B18: =IFERROR(__xludf.DUMMYFUNCTION("""COMPUTED_VALUE"""),"PODOLOGA") -> PODOLOGA | C18: =IFERROR(__xludf.DUMMYFUNCTION("""COMPUTED_VALUE"""),22.0) -> 22 | D18: =IFERROR(__xludf.DUMMYFUNCTION("""COMPUTED_VALUE"""),"KARINA MONTANARES") -> KARINA MONTANARES | E18: =IFERROR(__xludf.DUMMYFUNCTION("IFERROR(INDEX(QUERY(ENCUESTA_GESTION!$A$3:$H1000,""SELECT sum(H) WHERE B='""&$D18&""' "",0),2),"""")"),0.9) -> 0.9 | F18: =IFERROR(__xludf.DUMMYFUNCTION("IFERROR(INDEX(QUERY(ENCUESTA_REU!$A$3:$H1000,""SELECT sum(H) WHERE B='""&$D18&""' "",0),2),"""")")," ") | G18: =IFERROR(__xludf.DUMMYFUNCTION("IFERROR(INDEX(QUERY(ENCUESTA_DER!$A$3:$H1000,""SELECT sum(H) WHERE B='""&$D18&""' "",0),2),"""")"),2.5) -> 2.5 | H18: =SUM(E18:G18) -> 3.4
A19: =IFERROR(__xludf.DUMMYFUNCTION("""COMPUTED_VALUE"""),"CAT_C") -> CAT_C | B19: =IFERROR(__xludf.DUMMYFUNCTION("""COMPUTED_VALUE"""),"TENS") -> TENS | C19: =IFERROR(__xludf.DUMMYFUNCTION("""COMPUTED_VALUE"""),44.0) -> 44 | D19: =IFERROR(__xludf.DUMMYFUNCTION("""COMPUTED_VALUE"""),"DANIELA ROJAS GAMBOA") -> DANIELA ROJAS GAMBOA | E19: =IFERROR(__xludf.DUMMYFUNCTION("IFERROR(INDEX(QUERY(ENCUESTA_GESTION!$A$3:$H1000,""SELECT sum(H) WHERE B='""&$D19&""' "",0),2),"""")"),2.0) -> 2 | F19: =IFERROR(__xludf.DUMMYFUNCTION("IFERROR(INDEX(QUERY(ENCUESTA_REU!$A$3:$H1000,""SELECT sum(H) WHERE B='""&$D19&""' "",0),2),"""")"),2.2) -> 2.2 | G19: =IFERROR(__xludf.DUMMYFUNCTION("IFERROR(INDEX(QUERY(ENCUESTA_DER!$A$3:$H1000,""SELECT sum(H) WHERE B='""&$D19&""' "",0),2),"""")"),6.25) -> 6.25 | H19: =SUM(E19:G19) -> 10.45
A20: =IFERROR(__xludf.DUMMYFUNCTION("""COMPUTED_VALUE"""),"CAT_C") -> CAT_C | B20: =IFERROR(__xludf.DUMMYFUNCTION("""COMPUTED_VALUE"""),"TENS") -> TENS | C20: =IFERROR(__xludf.DUMMYFUNCTION("""COMPUTED_VALUE"""),44.0) -> 44 | D20: =IFERROR(__xludf.DUMMYFUNCTION("""COMPUTED_VALUE"""),"LUIS GONZALEZ SEPULVEDA") -> LUIS GONZALEZ SEPULVEDA | E20: =IFERROR(__xludf.DUMMYFUNCTION("IFERROR(INDEX(QUERY(ENCUESTA_GESTION!$A$3:$H1000,""SELECT sum(H) WHERE B='""&$D20&""' "",0),2),"""")"),2.0) -> 2 | F20: =IFERROR(__xludf.DUMMYFUNCTION("IFERROR(INDEX(QUERY(ENCUESTA_REU!$A$3:$H1000,""SELECT sum(H) WHERE B='""&$D20&""' "",0),2),"""")"),2.2) -> 2.2 | G20: =IFERROR(__xludf.DUMMYFUNCTION("IFERROR(INDEX(QUERY(ENCUESTA_DER!$A$3:$H1000,""SELECT sum(H) WHERE B='""&$D20&""' "",0),2),"""")"),6.25) -> 6.25 | H20: =SUM(E20:G20) -> 10.45
A21: =IFERROR(__xludf.DUMMYFUNCTION("""COMPUTED_VALUE"""),"CAT_C") -> CAT_C | B21: =IFERROR(__xludf.DUMMYFUNCTION("""COMPUTED_VALUE"""),"TONS") -> TONS | C21: =IFERROR(__xludf.DUMMYFUNCTION("""COMPUTED_VALUE"""),44.0) -> 44 | D21: =IFERROR(__xludf.DUMMYFUNCTION("""COMPUTED_VALUE"""),"ANGELA ZUÑIGA MUGA") -> ANGELA ZUÑIGA MUGA | E21: =IFERROR(__xludf.DUMMYFUNCTION("IFERROR(INDEX(QUERY(ENCUESTA_GESTION!$A$3:$H1000,""SELECT sum(H) WHERE B='""&$D21&""' "",0),2),"""")"),2.0) -> 2 | F21: =IFERROR(__xludf.DUMMYFUNCTION("IFERROR(INDEX(QUERY(ENCUESTA_REU!$A$3:$H1000,""SELECT sum(H) WHERE B='""&$D21&""' "",0),2),"""")"),2.2) -> 2.2 | G21: =IFERROR(__xludf.DUMMYFUNCTION("IFERROR(INDEX(QUERY(ENCUESTA_DER!$A$3:$H1000,""SELECT sum(H) WHERE B='""&$D21&""' "",0),2),"""")"),6.25) -> 6.25 | H21: =SUM(E21:G21) -> 10.45
A22: =IFERROR(__xludf.DUMMYFUNCTION("""COMPUTED_VALUE"""),"CAT_C") -> CAT_C | B22: =IFERROR(__xludf.DUMMYFUNCTION("""COMPUTED_VALUE"""),"TENS FARMACIA") -> TENS FARMACIA | C22: =IFERROR(__xludf.DUMMYFUNCTION("""COMPUTED_VALUE"""),44.0) -> 44 | D22: =IFERROR(__xludf.DUMMYFUNCTION("""COMPUTED_VALUE"""),"VALERIA NUÑEZ QUINCHEL") -> VALERIA NUÑEZ QUINCHEL | E22: =IFERROR(__xludf.DUMMYFUNCTION("IFERROR(INDEX(QUERY(ENCUESTA_GESTION!$A$3:$H1000,""SELECT sum(H) WHERE B='""&$D22&""' "",0),2),"""")"),2.0) -> 2 | F22: =IFERROR(__xludf.DUMMYFUNCTION("IFERROR(INDEX(QUERY(ENCUESTA_REU!$A$3:$H1000,""SELECT sum(H) WHERE B='""&$D22&""' "",0),2),"""")"),2.2) -> 2.2 | G22: =IFERROR(__xludf.DUMMYFUNCTION("IFERROR(INDEX(QUERY(ENCUESTA_DER!$A$3:$H1000,""SELECT sum(H) WHERE B='""&$D22&""' "",0),2),"""")"),6.25) -> 6.25 | H22: =SUM(E22:G22) -> 10.45
A23: =IFERROR(__xludf.DUMMYFUNCTION("""COMPUTED_VALUE"""),"CAT_C") -> CAT_C | B23: =IFERROR(__xludf.DUMMYFUNCTION("""COMPUTED_VALUE"""),"TENS") -> TENS | C23: =IFERROR(__xludf.DUMMYFUNCTION("""COMPUTED_VALUE"""),44.0) -> 44 | D23: =IFERROR(__xludf.DUMMYFUNCTION("""COMPUTED_VALUE"""),"MYRRHA ANDAUR MARTINEZ") -> MYRRHA ANDAUR MARTINEZ | E23: =IFERROR(__xludf.DUMMYFUNCTION("IFERROR(INDEX(QUERY(ENCUESTA_GESTION!$A$3:$H1000,""SELECT sum(H) WHERE B='""&$D23&""' "",0),2),"""")"),2.0) -> 2 | F23: =IFERROR(__xludf.DUMMYFUNCTION("IFERROR(INDEX(QUERY(ENCUESTA_REU!$A$3:$H1000,""SELECT sum(H) WHERE B='""&$D23&""' "",0),2),"""")"),2.2) -> 2.2 | G23: =IFERROR(__xludf.DUMMYFUNCTION("IFERROR(INDEX(QUERY(ENCUESTA_DER!$A$3:$H1000,""SELECT sum(H) WHERE B='""&$D23&""' "",0),2),"""")"),6.25) -> 6.25 | H23: =SUM(E23:G23) -> 10.45
E24: =IFERROR(__xludf.DUMMYFUNCTION("IFERROR(INDEX(QUERY(ENCUESTA_GESTION!$A$3:$H1000,""SELECT sum(H) WHERE B='""&$D24&""' "",0),2),"""")"),0.0) -> 0 | F24: =IFERROR(__xludf.DUMMYFUNCTION("IFERROR(INDEX(QUERY(ENCUESTA_REU!$A$3:$H1000,""SELECT sum(H) WHERE B='""&$D24&""' "",0),2),"""")"),0.0) -> 0 | G24: =IFERROR(__xludf.DUMMYFUNCTION("IFERROR(INDEX(QUERY(ENCUESTA_DER!$A$3:$H1000,""SELECT sum(H) WHERE B='""&$D24&""' "",0),2),"""")"),0.0) -> 0 | H24: =SUM(E24:G24) -> 0
E25: =IFERROR(__xludf.DUMMYFUNCTION("IFERROR(INDEX(QUERY(ENCUESTA_GESTION!$A$3:$H1000,""SELECT sum(H) WHERE B='""&$D25&""' "",0),2),"""")"),0.0) -> 0 | F25: =IFERROR(__xludf.DUMMYFUNCTION("IFERROR(INDEX(QUERY(ENCUESTA_REU!$A$3:$H1000,""SELECT sum(H) WHERE B='""&$D25&""' "",0),2),"""")"),0.0) -> 0 | G25: =IFERROR(__xludf.DUMMYFUNCTION("IFERROR(INDEX(QUERY(ENCUESTA_DER!$A$3:$H1000,""SELECT sum(H) WHERE B='""&$D25&""' "",0),2),"""")"),0.0) -> 0 | H25: =SUM(E25:G25) -> 0
E26: =IFERROR(__xludf.DUMMYFUNCTION("IFERROR(INDEX(QUERY(ENCUESTA_GESTION!$A$3:$H1000,""SELECT sum(H) WHERE B='""&$D26&""' "",0),2),"""")"),0.0) -> 0 | F26: =IFERROR(__xludf.DUMMYFUNCTION("IFERROR(INDEX(QUERY(ENCUESTA_REU!$A$3:$H1000,""SELECT sum(H) WHERE B='""&$D26&""' "",0),2),"""")"),0.0) -> 0 | G26: =IFERROR(__xludf.DUMMYFUNCTION("IFERROR(INDEX(QUERY(ENCUESTA_DER!$A$3:$H1000,""SELECT sum(H) WHERE B='""&$D26&""' "",0),2),"""")"),0.0) -> 0 | H26: =SUM(E26:G26) -> 0
E27: =IFERROR(__xludf.DUMMYFUNCTION("IFERROR(INDEX(QUERY(ENCUESTA_GESTION!$A$3:$H1000,""SELECT sum(H) WHERE B='""&$D27&""' "",0),2),"""")"),0.0) -> 0 | F27: =IFERROR(__xludf.DUMMYFUNCTION("IFERROR(INDEX(QUERY(ENCUESTA_REU!$A$3:$H1000,""SELECT sum(H) WHERE B='""&$D27&""' "",0),2),"""")"),0.0) -> 0 | G27: =IFERROR(__xludf.DUMMYFUNCTION("IFERROR(INDEX(QUERY(ENCUESTA_DER!$A$3:$H1000,""SELECT sum(H) WHERE B='""&$D27&""' "",0),2),"""")"),0.0) -> 0 | H27: =SUM(E27:G27) -> 0
E28: =IFERROR(__xludf.DUMMYFUNCTION("IFERROR(INDEX(QUERY(ENCUESTA_GESTION!$A$3:$H1000,""SELECT sum(H) WHERE B='""&$D28&""' "",0),2),"""")"),0.0) -> 0 | F28: =IFERROR(__xludf.DUMMYFUNCTION("IFERROR(INDEX(QUERY(ENCUESTA_REU!$A$3:$H1000,""SELECT sum(H) WHERE B='""&$D28&""' "",0),2),"""")"),0.0) -> 0 | G28: =IFERROR(__xludf.DUMMYFUNCTION("IFERROR(INDEX(QUERY(ENCUESTA_DER!$A$3:$H1000,""SELECT sum(H) WHERE B='""&$D28&""' "",0),2),"""")"),0.0) -> 0 | H28: =SUM(E28:G28) -> 0
E29: =IFERROR(__xludf.DUMMYFUNCTION("IFERROR(INDEX(QUERY(ENCUESTA_GESTION!$A$3:$H1000,""SELECT sum(H) WHERE B='""&$D29&""' "",0),2),"""")"),0.0) -> 0 | F29: =IFERROR(__xludf.DUMMYFUNCTION("IFERROR(INDEX(QUERY(ENCUESTA_REU!$A$3:$H1000,""SELECT sum(H) WHERE B='""&$D29&""' "",0),2),"""")"),0.0) -> 0 | G29: =IFERROR(__xludf.DUMMYFUNCTION("IFERROR(INDEX(QUERY(ENCUESTA_DER!$A$3:$H1000,""SELECT sum(H) WHERE B='""&$D29&""' "",0),2),"""")"),0.0) -> 0 | H29: =SUM(E29:G29) -> 0
E30: =IFERROR(__xludf.DUMMYFUNCTION("IFERROR(INDEX(QUERY(ENCUESTA_GESTION!$A$3:$H1000,""SELECT sum(H) WHERE B='""&$D30&""' "",0),2),"""")"),0.0) -> 0 | F30: =IFERROR(__xludf.DUMMYFUNCTION("IFERROR(INDEX(QUERY(ENCUESTA_REU!$A$3:$H1000,""SELECT sum(H) WHERE B='""&$D30&""' "",0),2),"""")"),0.0) -> 0 | G30: =IFERROR(__xludf.DUMMYFUNCTION("IFERROR(INDEX(QUERY(ENCUESTA_DER!$A$3:$H1000,""SELECT sum(H) WHERE B='""&$D30&""' "",0),2),"""")"),0.0) -> 0 | H30: =SUM(E30:G30) -> 0
E31: =IFERROR(__xludf.DUMMYFUNCTION("IFERROR(INDEX(QUERY(ENCUESTA_GESTION!$A$3:$H1000,""SELECT sum(H) WHERE B='""&$D31&""' "",0),2),"""")"),0.0) -> 0 | F31: =IFERROR(__xludf.DUMMYFUNCTION("IFERROR(INDEX(QUERY(ENCUESTA_REU!$A$3:$H1000,""SELECT sum(H) WHERE B='""&$D31&""' "",0),2),"""")"),0.0) -> 0 | G31: =IFERROR(__xludf.DUMMYFUNCTION("IFERROR(INDEX(QUERY(ENCUESTA_DER!$A$3:$H1000,""SELECT sum(H) WHERE B='""&$D31&""' "",0),2),"""")"),0.0) -> 0 | H31: =SUM(E31:G31) -> 0
E32: =IFERROR(__xludf.DUMMYFUNCTION("IFERROR(INDEX(QUERY(ENCUESTA_GESTION!$A$3:$H1000,""SELECT sum(H) WHERE B='""&$D32&""' "",0),2),"""")"),0.0) -> 0 | F32: =IFERROR(__xludf.DUMMYFUNCTION("IFERROR(INDEX(QUERY(ENCUESTA_REU!$A$3:$H1000,""SELECT sum(H) WHERE B='""&$D32&""' "",0),2),"""")"),0.0) -> 0 | G32: =IFERROR(__xludf.DUMMYFUNCTION("IFERROR(INDEX(QUERY(ENCUESTA_DER!$A$3:$H1000,""SELECT sum(H) WHERE B='""&$D32&""' "",0),2),"""")"),0.0) -> 0 | H32: =SUM(E32:G32) -> 0
E33: =IFERROR(__xludf.DUMMYFUNCTION("IFERROR(INDEX(QUERY(ENCUESTA_GESTION!$A$3:$H1000,""SELECT sum(H) WHERE B='""&$D33&""' "",0),2),"""")"),0.0) -> 0 | F33: =IFERROR(__xludf.DUMMYFUNCTION("IFERROR(INDEX(QUERY(ENCUESTA_REU!$A$3:$H1000,""SELECT sum(H) WHERE B='""&$D33&""' "",0),2),"""")"),0.0) -> 0 | G33: =IFERROR(__xludf.DUMMYFUNCTION("IFERROR(INDEX(QUERY(ENCUESTA_DER!$A$3:$H1000,""SELECT sum(H) WHERE B='""&$D33&""' "",0),2),"""")"),0.0) -> 0 | H33: =SUM(E33:G33) -> 0
E34: =IFERROR(__xludf.DUMMYFUNCTION("IFERROR(INDEX(QUERY(ENCUESTA_GESTION!$A$3:$H1000,""SELECT sum(H) WHERE B='""&$D34&""' "",0),2),"""")"),0.0) -> 0 | F34: =IFERROR(__xludf.DUMMYFUNCTION("IFERROR(INDEX(QUERY(ENCUESTA_REU!$A$3:$H1000,""SELECT sum(H) WHERE B='""&$D34&""' "",0),2),"""")"),0.0) -> 0 | G34: =IFERROR(__xludf.DUMMYFUNCTION("IFERROR(INDEX(QUERY(ENCUESTA_DER!$A$3:$H1000,""SELECT sum(H) WHERE B='""&$D34&""' "",0),2),"""")"),0.0) -> 0 | H34: =SUM(E34:G34) -> 0
E35: =IFERROR(__xludf.DUMMYFUNCTION("IFERROR(INDEX(QUERY(ENCUESTA_GESTION!$A$3:$H1000,""SELECT sum(H) WHERE B='""&$D35&""' "",0),2),"""")"),0.0) -> 0 | F35: =IFERROR(__xludf.DUMMYFUNCTION("IFERROR(INDEX(QUERY(ENCUESTA_REU!$A$3:$H1000,""SELECT sum(H) WHERE B='""&$D35&""' "",0),2),"""")"),0.0) -> 0 | G35: =IFERROR(__xludf.DUMMYFUNCTION("IFERROR(INDEX(QUERY(ENCUESTA_DER!$A$3:$H1000,""SELECT sum(H) WHERE B='""&$D35&""' "",0),2),"""")"),0.0) -> 0 | H35: =SUM(E35:G35) -> 0
E36: =IFERROR(__xludf.DUMMYFUNCTION("IFERROR(INDEX(QUERY(ENCUESTA_GESTION!$A$3:$H1000,""SELECT sum(H) WHERE B='""&$D36&""' "",0),2),"""")"),0.0) -> 0 | F36: =IFERROR(__xludf.DUMMYFUNCTION("IFERROR(INDEX(QUERY(ENCUESTA_REU!$A$3:$H1000,""SELECT sum(H) WHERE B='""&$D36&""' "",0),2),"""")"),0.0) -> 0 | G36: =IFERROR(__xludf.DUMMYFUNCTION("IFERROR(INDEX(QUERY(ENCUESTA_DER!$A$3:$H1000,""SELECT sum(H) WHERE B='""&$D36&""' "",0),2),"""")"),0.0) -> 0 | H36: =SUM(E36:G36) -> 0
E37: =IFERROR(__xludf.DUMMYFUNCTION("IFERROR(INDEX(QUERY(ENCUESTA_GESTION!$A$3:$H1000,""SELECT sum(H) WHERE B='""&$D37&""' "",0),2),"""")"),0.0) -> 0 | F37: =IFERROR(__xludf.DUMMYFUNCTION("IFERROR(INDEX(QUERY(ENCUESTA_REU!$A$3:$H1000,""SELECT sum(H) WHERE B='""&$D37&""' "",0),2),"""")"),0.0) -> 0 | G37: =IFERROR(__xludf.DUMMYFUNCTION("IFERROR(INDEX(QUERY(ENCUESTA_DER!$A$3:$H1000,""SELECT sum(H) WHERE B='""&$D37&""' "",0),2),"""")"),0.0) -> 0 | H37: =SUM(E37:G37) -> 0
E38: =IFERROR(__xludf.DUMMYFUNCTION("IFERROR(INDEX(QUERY(ENCUESTA_GESTION!$A$3:$H1000,""SELECT sum(H) WHERE B='""&$D38&""' "",0),2),"""")"),0.0) -> 0 | F38: =IFERROR(__xludf.DUMMYFUNCTION("IFERROR(INDEX(QUERY(ENCUESTA_REU!$A$3:$H1000,""SELECT sum(H) WHERE B='""&$D38&""' "",0),2),"""")"),0.0) -> 0 | G38: =IFERROR(__xludf.DUMMYFUNCTION("IFERROR(INDEX(QUERY(ENCUESTA_DER!$A$3:$H1000,""SELECT sum(H) WHERE B='""&$D38&""' "",0),2),"""")"),0.0) -> 0 | H38: =SUM(E38:G38) -> 0
E39: =IFERROR(__xludf.DUMMYFUNCTION("IFERROR(INDEX(QUERY(ENCUESTA_GESTION!$A$3:$H1000,""SELECT sum(H) WHERE B='""&$D39&""' "",0),2),"""")"),0.0) -> 0 | F39: =IFERROR(__xludf.DUMMYFUNCTION("IFERROR(INDEX(QUERY(ENCUESTA_REU!$A$3:$H1000,""SELECT sum(H) WHERE B='""&$D39&""' "",0),2),"""")"),0.0) -> 0 | G39: =IFERROR(__xludf.DUMMYFUNCTION("IFERROR(INDEX(QUERY(ENCUESTA_DER!$A$3:$H1000,""SELECT sum(H) WHERE B='""&$D39&""' "",0),2),"""")"),0.0) -> 0 | H39: =SUM(E39:G39) -> 0
E40: =IFERROR(__xludf.DUMMYFUNCTION("IFERROR(INDEX(QUERY(ENCUESTA_GESTION!$A$3:$H1000,""SELECT sum(H) WHERE B='""&$D40&""' "",0),2),"""")"),0.0) -> 0 | F40: =IFERROR(__xludf.DUMMYFUNCTION("IFERROR(INDEX(QUERY(ENCUESTA_REU!$A$3:$H1000,""SELECT sum(H) WHERE B='""&$D40&""' "",0),2),"""")"),0.0) -> 0 | G40: =IFERROR(__xludf.DUMMYFUNCTION("IFERROR(INDEX(QUERY(ENCUESTA_DER!$A$3:$H1000,""SELECT sum(H) WHERE B='""&$D40&""' "",0),2),"""")"),0.0) -> 0 | H40: =SUM(E40:G40) -> 0
...

Sheet CALEND_REUNIONxPROF
B1: CALENDARIO REUNIONES POR PROFESIONAL | I1: SEMANA: | J1: 1
C3: PROFESIONAL: | D3: JUAN PABLO ACEITUNO JARA | H3: DERECHO FUNCIONARIO | I3: GESTION | J3: REUNION | K3: TOTAL HNC
E4: {=IF(D3="TOD@S","",CONCATENATE("Jornada: ",XLOOKUP(D3,FUNC!E:E,FUNC!D:D)," horas"))} -> #N/A | H4: =IFERROR(__xludf.DUMMYFUNCTION("IFERROR(INDEX(QUERY(CONSO_ENCUESTAS!$A$4:$H32,""SELECT sum(G) WHERE A='""&$D3&""' AND B='""&$H$3&""' "",0),2),""-"")"),"-") -> - | I4: =IFERROR(__xludf.DUMMYFUNCTION("IFERROR(INDEX(QUERY(CONSO_ENCUESTAS!$A$4:$H32,""SELECT sum(G) WHERE A='""&$D3&""' AND B='""&$I$3&""' "",0),2),""-"")"),"-") -> - | J4: =IFERROR(__xludf.DUMMYFUNCTION("IFERROR(INDEX(QUERY(CONSO_ENCUESTAS!$A$4:$H32,""SELECT sum(G) WHERE A='""&$D3&""' AND B='""&$J$3&""' "",0),2),""-"")"),"-") -> - | K4: =SUM(H4:J4) -> 0
A6: =IF(J1="TODAS","","AND I="&J1&" ") -> AND I=1 | C6: =IFERROR(__xludf.DUMMYFUNCTION("QUERY(ENCUESTA_REU!B2:Q32,""SELECT B,D,E WHERE B IS NOT NULL ""&A7&"" ORDER BY B "",1)"),"FUNCIONARIO") -> FUNCIONARIO | D6: =IFERROR(__xludf.DUMMYFUNCTION("""COMPUTED_VALUE"""),"AMBITO") -> AMBITO | E6: =IFERROR(__xludf.DUMMYFUNCTION("""COMPUTED_VALUE"""),"ACTIVIDAD") -> ACTIVIDAD | F6: CALEND | G6: SEM | H6: DIA | I6: DESDE | J6: HASTA | K6: FREC (nro veces año) | L6: TIEMPO reunion
A7: =IF(D3="TOD@S","","AND B='"&D3&"' ") -> AND B='JUAN PABLO ACEITUNO JARA' | F7: =IFERROR(XLOOKUP($E7,BD_REF_REUNIONES!$D:$D,BD_REF_REUNIONES!H:H),"") | G7: =IFERROR(XLOOKUP($E7,BD_REF_REUNIONES!$D:$D,BD_REF_REUNIONES!I:I),"") | H7: =IFERROR(XLOOKUP($E7,BD_REF_REUNIONES!$D:$D,BD_REF_REUNIONES!J:J),"") | I7: =IFERROR(XLOOKUP($E7,BD_REF_REUNIONES!$D:$D,BD_REF_REUNIONES!K:K),"") | J7: =IFERROR(XLOOKUP($E7,BD_REF_REUNIONES!$D:$D,BD_REF_REUNIONES!L:L),"") | K7: =IFERROR(XLOOKUP($E7,BD_REF_REUNIONES!$D:$D,BD_REF_REUNIONES!M:M),"") | L7: =IFERROR(XLOOKUP($E7,BD_REF_REUNIONES!$D:$D,BD_REF_REUNIONES!N:N),"")
F8: =IFERROR(XLOOKUP($E8,BD_REF_REUNIONES!$D:$D,BD_REF_REUNIONES!H:H),"") | G8: =IFERROR(XLOOKUP($E8,BD_REF_REUNIONES!$D:$D,BD_REF_REUNIONES!I:I),"") | H8: =IFERROR(XLOOKUP($E8,BD_REF_REUNIONES!$D:$D,BD_REF_REUNIONES!J:J),"") | I8: =IFERROR(XLOOKUP($E8,BD_REF_REUNIONES!$D:$D,BD_REF_REUNIONES!K:K),"") | J8: =IFERROR(XLOOKUP($E8,BD_REF_REUNIONES!$D:$D,BD_REF_REUNIONES!L:L),"") | K8: =IFERROR(XLOOKUP($E8,BD_REF_REUNIONES!$D:$D,BD_REF_REUNIONES!M:M),"") | L8: =IFERROR(XLOOKUP($E8,BD_REF_REUNIONES!$D:$D,BD_REF_REUNIONES!N:N),"")
F9: =IFERROR(XLOOKUP($E9,BD_REF_REUNIONES!$D:$D,BD_REF_REUNIONES!H:H),"") | G9: =IFERROR(XLOOKUP($E9,BD_REF_REUNIONES!$D:$D,BD_REF_REUNIONES!I:I),"") | H9: =IFERROR(XLOOKUP($E9,BD_REF_REUNIONES!$D:$D,BD_REF_REUNIONES!J:J),"") | I9: =IFERROR(XLOOKUP($E9,BD_REF_REUNIONES!$D:$D,BD_REF_REUNIONES!K:K),"") | J9: =IFERROR(XLOOKUP($E9,BD_REF_REUNIONES!$D:$D,BD_REF_REUNIONES!L:L),"") | K9: =IFERROR(XLOOKUP($E9,BD_REF_REUNIONES!$D:$D,BD_REF_REUNIONES!M:M),"") | L9: =IFERROR(XLOOKUP($E9,BD_REF_REUNIONES!$D:$D,BD_REF_REUNIONES!N:N),"")
F10: =IFERROR(XLOOKUP($E10,BD_REF_REUNIONES!$D:$D,BD_REF_REUNIONES!H:H),"") | G10: =IFERROR(XLOOKUP($E10,BD_REF_REUNIONES!$D:$D,BD_REF_REUNIONES!I:I),"") | H10: =IFERROR(XLOOKUP($E10,BD_REF_REUNIONES!$D:$D,BD_REF_REUNIONES!J:J),"") | I10: =IFERROR(XLOOKUP($E10,BD_REF_REUNIONES!$D:$D,BD_REF_REUNIONES!K:K),"") | J10: =IFERROR(XLOOKUP($E10,BD_REF_REUNIONES!$D:$D,BD_REF_REUNIONES!L:L),"") | K10: =IFERROR(XLOOKUP($E10,BD_REF_REUNIONES!$D:$D,BD_REF_REUNIONES!M:M),"") | L10: =IFERROR(XLOOKUP($E10,BD_REF_REUNIONES!$D:$D,BD_REF_REUNIONES!N:N),"")
F11: =IFERROR(XLOOKUP($E11,BD_REF_REUNIONES!$D:$D,BD_REF_REUNIONES!H:H),"") | G11: =IFERROR(XLOOKUP($E11,BD_REF_REUNIONES!$D:$D,BD_REF_REUNIONES!I:I),"") | H11: =IFERROR(XLOOKUP($E11,BD_REF_REUNIONES!$D:$D,BD_REF_REUNIONES!J:J),"") | I11: =IFERROR(XLOOKUP($E11,BD_REF_REUNIONES!$D:$D,BD_REF_REUNIONES!K:K),"") | J11: =IFERROR(XLOOKUP($E11,BD_REF_REUNIONES!$D:$D,BD_REF_REUNIONES!L:L),"") | K11: =IFERROR(XLOOKUP($E11,BD_REF_REUNIONES!$D:$D,BD_REF_REUNIONES!M:M),"") | L11: =IFERROR(XLOOKUP($E11,BD_REF_REUNIONES!$D:$D,BD_REF_REUNIONES!N:N),"")
F12: =IFERROR(XLOOKUP($E12,BD_REF_REUNIONES!$D:$D,BD_REF_REUNIONES!H:H),"") | G12: =IFERROR(XLOOKUP($E12,BD_REF_REUNIONES!$D:$D,BD_REF_REUNIONES!I:I),"") | H12: =IFERROR(XLOOKUP($E12,BD_REF_REUNIONES!$D:$D,BD_REF_REUNIONES!J:J),"") | I12: =IFERROR(XLOOKUP($E12,BD_REF_REUNIONES!$D:$D,BD_REF_REUNIONES!K:K),"") | J12: =IFERROR(XLOOKUP($E12,BD_REF_REUNIONES!$D:$D,BD_REF_REUNIONES!L:L),"") | K12: =IFERROR(XLOOKUP($E12,BD_REF_REUNIONES!$D:$D,BD_REF_REUNIONES!M:M),"") | L12: =IFERROR(XLOOKUP($E12,BD_REF_REUNIONES!$D:$D,BD_REF_REUNIONES!N:N),"")
F13: =IFERROR(XLOOKUP($E13,BD_REF_REUNIONES!$D:$D,BD_REF_REUNIONES!H:H),"") | G13: =IFERROR(XLOOKUP($E13,BD_REF_REUNIONES!$D:$D,BD_REF_REUNIONES!I:I),"") | H13: =IFERROR(XLOOKUP($E13,BD_REF_REUNIONES!$D:$D,BD_REF_REUNIONES!J:J),"") | I13: =IFERROR(XLOOKUP($E13,BD_REF_REUNIONES!$D:$D,BD_REF_REUNIONES!K:K),"") | J13: =IFERROR(XLOOKUP($E13,BD_REF_REUNIONES!$D:$D,BD_REF_REUNIONES!L:L),"") | K13: =IFERROR(XLOOKUP($E13,BD_REF_REUNIONES!$D:$D,BD_REF_REUNIONES!M:M),"") | L13: =IFERROR(XLOOKUP($E13,BD_REF_REUNIONES!$D:$D,BD_REF_REUNIONES!N:N),"")
F14: =IFERROR(XLOOKUP($E14,BD_REF_REUNIONES!$D:$D,BD_REF_REUNIONES!H:H),"") | G14: =IFERROR(XLOOKUP($E14,BD_REF_REUNIONES!$D:$D,BD_REF_REUNIONES!I:I),"") | H14: =IFERROR(XLOOKUP($E14,BD_REF_REUNIONES!$D:$D,BD_REF_REUNIONES!J:J),"") | I14: =IFERROR(XLOOKUP($E14,BD_REF_REUNIONES!$D:$D,BD_REF_REUNIONES!K:K),"") | J14: =IFERROR(XLOOKUP($E14,BD_REF_REUNIONES!$D:$D,BD_REF_REUNIONES!L:L),"") | K14: =IFERROR(XLOOKUP($E14,BD_REF_REUNIONES!$D:$D,BD_REF_REUNIONES!M:M),"") | L14: =IFERROR(XLOOKUP($E14,BD_REF_REUNIONES!$D:$D,BD_REF_REUNIONES!N:N),"")
F15: =IFERROR(XLOOKUP($E15,BD_REF_REUNIONES!$D:$D,BD_REF_REUNIONES!H:H),"") | G15: =IFERROR(XLOOKUP($E15,BD_REF_REUNIONES!$D:$D,BD_REF_REUNIONES!I:I),"") | H15: =IFERROR(XLOOKUP($E15,BD_REF_REUNIONES!$D:$D,BD_REF_REUNIONES!J:J),"") | I15: =IFERROR(XLOOKUP($E15,BD_REF_REUNIONES!$D:$D,BD_REF_REUNIONES!K:K),"") | J15: =IFERROR(XLOOKUP($E15,BD_REF_REUNIONES!$D:$D,BD_REF_REUNIONES!L:L),"") | K15: =IFERROR(XLOOKUP($E15,BD_REF_REUNIONES!$D:$D,BD_REF_REUNIONES!M:M),"") | L15: =IFERROR(XLOOKUP($E15,BD_REF_REUNIONES!$D:$D,BD_REF_REUNIONES!N:N),"")
F16: =IFERROR(XLOOKUP($E16,BD_REF_REUNIONES!$D:$D,BD_REF_REUNIONES!H:H),"") | G16: =IFERROR(XLOOKUP($E16,BD_REF_REUNIONES!$D:$D,BD_REF_REUNIONES!I:I),"") | H16: =IFERROR(XLOOKUP($E16,BD_REF_REUNIONES!$D:$D,BD_REF_REUNIONES!J:J),"") | I16: =IFERROR(XLOOKUP($E16,BD_REF_REUNIONES!$D:$D,BD_REF_REUNIONES!K:K),"") | J16: =IFERROR(XLOOKUP($E16,BD_REF_REUNIONES!$D:$D,BD_REF_REUNIONES!L:L),"") | K16: =IFERROR(XLOOKUP($E16,BD_REF_REUNIONES!$D:$D,BD_REF_REUNIONES!M:M),"") | L16: =IFERROR(XLOOKUP($E16,BD_REF_REUNIONES!$D:$D,BD_REF_REUNIONES!N:N),"")
F17: =IFERROR(XLOOKUP($E17,BD_REF_REUNIONES!$D:$D,BD_REF_REUNIONES!H:H),"") | G17: =IFERROR(XLOOKUP($E17,BD_REF_REUNIONES!$D:$D,BD_REF_REUNIONES!I:I),"") | H17: =IFERROR(XLOOKUP($E17,BD_REF_REUNIONES!$D:$D,BD_REF_REUNIONES!J:J),"") | I17: =IFERROR(XLOOKUP($E17,BD_REF_REUNIONES!$D:$D,BD_REF_REUNIONES!K:K),"") | J17: =IFERROR(XLOOKUP($E17,BD_REF_REUNIONES!$D:$D,BD_REF_REUNIONES!L:L),"") | K17: =IFERROR(XLOOKUP($E17,BD_REF_REUNIONES!$D:$D,BD_REF_REUNIONES!M:M),"") | L17: =IFERROR(XLOOKUP($E17,BD_REF_REUNIONES!$D:$D,BD_REF_REUNIONES!N:N),"")
F18: =IFERROR(XLOOKUP($E18,BD_REF_REUNIONES!$D:$D,BD_REF_REUNIONES!H:H),"") | G18: =IFERROR(XLOOKUP($E18,BD_REF_REUNIONES!$D:$D,BD_REF_REUNIONES!I:I),"") | H18: =IFERROR(XLOOKUP($E18,BD_REF_REUNIONES!$D:$D,BD_REF_REUNIONES!J:J),"") | I18: =IFERROR(XLOOKUP($E18,BD_REF_REUNIONES!$D:$D,BD_REF_REUNIONES!K:K),"") | J18: =IFERROR(XLOOKUP($E18,BD_REF_REUNIONES!$D:$D,BD_REF_REUNIONES!L:L),"") | K18: =IFERROR(XLOOKUP($E18,BD_REF_REUNIONES!$D:$D,BD_REF_REUNIONES!M:M),"") | L18: =IFERROR(XLOOKUP($E18,BD_REF_REUNIONES!$D:$D,BD_REF_REUNIONES!N:N),"")
F19: =IFERROR(XLOOKUP($E19,BD_REF_REUNIONES!$D:$D,BD_REF_REUNIONES!H:H),"") | G19: =IFERROR(XLOOKUP($E19,BD_REF_REUNIONES!$D:$D,BD_REF_REUNIONES!I:I),"") | H19: =IFERROR(XLOOKUP($E19,BD_REF_REUNIONES!$D:$D,BD_REF_REUNIONES!J:J),"") | I19: =IFERROR(XLOOKUP($E19,BD_REF_REUNIONES!$D:$D,BD_REF_REUNIONES!K:K),"") | J19: =IFERROR(XLOOKUP($E19,BD_REF_REUNIONES!$D:$D,BD_REF_REUNIONES!L:L),"") | K19: =IFERROR(XLOOKUP($E19,BD_REF_REUNIONES!$D:$D,BD_REF_REUNIONES!M:M),"") | L19: =IFERROR(XLOOKUP($E19,BD_REF_REUNIONES!$D:$D,BD_REF_REUNIONES!N:N),"")
... F32: =IFERROR(XLOOKUP($E32,BD_REF_REUNIONES!$D:$D,BD_REF_REUNIONES!H:H),"") | G32: =IFERROR(XLOOKUP($E32,BD_REF_REUNIONES!$D:$D,BD_REF_REUNIONES!I:I),"") | H32: =IFERROR(XLOOKUP($E32,BD_REF_REUNIONES!$D:$D,BD_REF_REUNIONES!J:J),"") | I32: =IFERROR(XLOOKUP($E32,BD_REF_REUNIONES!$D:$D,BD_REF_REUNIONES!K:K),"") | J32: =IFERROR(XLOOKUP($E32,BD_REF_REUNIONES!$D:$D,BD_REF_REUNIONES!L:L),"") | K32: =IFERROR(XLOOKUP($E32,BD_REF_REUNIONES!$D:$D,BD_REF_REUNIONES!M:M),"") | L32: =IFERROR(XLOOKUP($E32,BD_REF_REUNIONES!$D:$D,BD_REF_REUNIONES!N:N),"")

Sheet CALENDARIO_REUNIONES
B1: CELENDARIO SEMANAL DE REUNIONES | K1: DIA: | L1: TODOS
K2: SEMANA: | L2: Todas
J4: =IF(L1="Todos","",IF(L1="LUNES","AND J=1 ",IF(L1="MARTES","AND J=2 ",IF(L1="MIÉRCOLES","AND J=3 ",IF(L1="JUEVES","AND J=4 ",IF(L1="VIERNES","AND J=5 ")))))) | K4: =IF(L2="Todas","","AND I="&L2&" ")
B5: SEM | C5: DIA | D5: REUNION | E5: CALENDARIO | F5: DESDE | G5: HASTA | H5: LUNES | I5: MARTES | J5: MIÉRCOLES | K5: JUEVES | L5: VIERNES
B6: =IFERROR(__xludf.DUMMYFUNCTION("QUERY(BD_REF_REUNIONES!A4:O84,""SELECT I,J,D,H,K,L WHERE I IS NOT NULL ""&K4&J4&"" ORDER BY I,J,K,D,H,L"",1)"),"#REF!") -> #REF! | H6: 1, Lu | I6: 2,Ma | J6: 3,Mi | K6: 4,Ju | L6: 5,Vi
H7: =IF($C7=1,D7,"") | I7: =IF($C7=2,D7,"") | J7: =IF($C7=3,D7,"") | K7: =IF($C7=4,D7,"") | L7: =IF($C7=5,D7,"")
H8: =IF($C8=1,D8,"") | I8: =IF($C8=2,D8,"") | J8: =IF($C8=3,D8,"") | K8: =IF($C8=4,D8,"") | L8: =IF($C8=5,D8,"")
H9: =IF($C9=1,D9,"") | I9: =IF($C9=2,D9,"") | J9: =IF($C9=3,D9,"") | K9: =IF($C9=4,D9,"") | L9: =IF($C9=5,D9,"")
H10: =IF($C10=1,D10,"") | I10: =IF($C10=2,D10,"") | J10: =IF($C10=3,D10,"") | K10: =IF($C10=4,D10,"") | L10: =IF($C10=5,D10,"")
H11: =IF($C11=1,D11,"") | I11: =IF($C11=2,D11,"") | J11: =IF($C11=3,D11,"") | K11: =IF($C11=4,D11,"") | L11: =IF($C11=5,D11,"")
H12: =IF($C12=1,D12,"") | I12: =IF($C12=2,D12,"") | J12: =IF($C12=3,D12,"") | K12: =IF($C12=4,D12,"") | L12: =IF($C12=5,D12,"")
H13: =IF($C13=1,D13,"") | I13: =IF($C13=2,D13,"") | J13: =IF($C13=3,D13,"") | K13: =IF($C13=4,D13,"") | L13: =IF($C13=5,D13,"")
H14: =IF($C14=1,D14,"") | I14: =IF($C14=2,D14,"") | J14: =IF($C14=3,D14,"") | K14: =IF($C14=4,D14,"") | L14: =IF($C14=5,D14,"")
H15: =IF($C15=1,D15,"") | I15: =IF($C15=2,D15,"") | J15: =IF($C15=3,D15,"") | K15: =IF($C15=4,D15,"") | L15: =IF($C15=5,D15,"")
H16: =IF($C16=1,D16,"") | I16: =IF($C16=2,D16,"") | J16: =IF($C16=3,D16,"") | K16: =IF($C16=4,D16,"") | L16: =IF($C16=5,D16,"")
H17: =IF($C17=1,D17,"") | I17: =IF($C17=2,D17,"") | J17: =IF($C17=3,D17,"") | K17: =IF($C17=4,D17,"") | L17: =IF($C17=5,D17,"")
H18: =IF($C18=1,D18,"") | I18: =IF($C18=2,D18,"") | J18: =IF($C18=3,D18,"") | K18: =IF($C18=4,D18,"") | L18: =IF($C18=5,D18,"")
... H73: =IF($C73=1,D73,"") | I73: =IF($C73=2,D73,"") | J73: =IF($C73=3,D73,"") | K73: =IF($C73=4,D73,"") | L73: =IF($C73=5,D73,"")

Sheet BORRAR_REPETIDOS
A1: =IFERROR(__xludf.DUMMYFUNCTION("QUERY(QUERY(CONSO_ENCUESTAS!A4:H1000,""SELECT B,A,C,D,COUNT(H) WHERE B IS NOT NULL GROUP BY B,A,C,D"",1),""SELECT * WHERE Col5 >=2"",1)"),"TIPO") -> TIPO | B1: =IFERROR(__xludf.DUMMYFUNCTION("""COMPUTED_VALUE"""),"FUNCIONARIO") -> FUNCIONARIO | C1: =IFERROR(__xludf.DUMMYFUNCTION("""COMPUTED_VALUE"""),"AMBITO") -> AMBITO | D1: =IFERROR(__xludf.DUMMYFUNCTION("""COMPUTED_VALUE"""),"ACTIVIDAD") -> ACTIVIDAD | E1: =IFERROR(__xludf.DUMMYFUNCTION("""COMPUTED_VALUE"""),"count CHECK ") -> count CHECK
A2: =IFERROR(__xludf.DUMMYFUNCTION("""COMPUTED_VALUE"""),"GESTION") -> GESTION | B2: =IFERROR(__xludf.DUMMYFUNCTION("""COMPUTED_VALUE"""),"CAROL AMBO AMPUERO") -> CAROL AMBO AMPUERO | C2: =IFERROR(__xludf.DUMMYFUNCTION("""COMPUTED_VALUE"""),"PROGRAMA - TRANSVERSAL") -> PROGRAMA - TRANSVERSAL | D2: =IFERROR(__xludf.DUMMYFUNCTION("""COMPUTED_VALUE"""),"ENCARGADO PROGRAMA (3 HRS)") -> ENCARGADO PROGRAMA (3 HRS) | E2: =IFERROR(__xludf.DUMMYFUNCTION("""COMPUTED_VALUE"""),2.0) -> 2
A3: =IFERROR(__xludf.DUMMYFUNCTION("""COMPUTED_VALUE"""),"GESTION") -> GESTION | B3: =IFERROR(__xludf.DUMMYFUNCTION("""COMPUTED_VALUE"""),"SORAYA CRUCES DIAZ") -> SORAYA CRUCES DIAZ | C3: =IFERROR(__xludf.DUMMYFUNCTION("""COMPUTED_VALUE"""),"PROGRAMA - TRANSVERSAL") -> PROGRAMA - TRANSVERSAL | D3: =IFERROR(__xludf.DUMMYFUNCTION("""COMPUTED_VALUE"""),"ENCARGADO PROGRAMA (1 HRS)") -> ENCARGADO PROGRAMA (1 HRS) | E3: =IFERROR(__xludf.DUMMYFUNCTION("""COMPUTED_VALUE"""),2.0) -> 2

Sheet BORRAR_NO _VIGENTE
A1: =IFERROR(__xludf.DUMMYFUNCTION("QUERY(QUERY(CONSO_ENCUESTAS!A4:I1032,""SELECT B,A,C,D,I,COUNT(H) WHERE B IS NOT NULL GROUP BY B,A,C,D,I"",1),""SELECT * WHERE Col5 matches '.*NO.*'"",1)"),"TIPO") -> TIPO | B1: =IFERROR(__xludf.DUMMYFUNCTION("""COMPUTED_VALUE"""),"FUNCIONARIO") -> FUNCIONARIO | C1: =IFERROR(__xludf.DUMMYFUNCTION("""COMPUTED_VALUE"""),"AMBITO") -> AMBITO | D1: =IFERROR(__xludf.DUMMYFUNCTION("""COMPUTED_VALUE"""),"ACTIVIDAD") -> ACTIVIDAD | E1: =IFERROR(__xludf.DUMMYFUNCTION("""COMPUTED_VALUE""")," ESTADO ") -> ESTADO | F1: =IFERROR(__xludf.DUMMYFUNCTION("""COMPUTED_VALUE"""),"count CHECK ") -> count CHECK

Sheet Horas_FUNC
B1: DOTACION FUNCIONARIOS
A4: =IFERROR(__xludf.DUMMYFUNCTION("CONCATENATE(""nro profesionales = "",COUNTUNIQUE(A7:A221))"),"nro profesionales = 3") -> nro profesionales = 3
C5: FUNCIONARIO | D5: sum sum HORAS | E5: sum DIAS PERMISO ADMINISTRATIVO | F5: sum DIAS FERIADO LEGAL | G5: sum DIAS CAPACITACION | H5: sum TOTAL DIAS AUSENCIA JUSTIF (año) | I5: sum TOTAL DIAS DISPONIBLES (año) | J5: sum TOTAL SEMANAS DISPONIBLES (año) | K5: sum TOTAL HORAS DISPONIBLES (año) | L5: GESTIÓN | M5: REUNION | N5: DERECHO FUNCIONARIO | O5: HORAS NO CLINICAS (semana) | P5: HORAS CLINICAS (semana) | Q5: HORAS NO CLINICAS (año) | R5: HORAS CLINICAS (año)
